2025-07-26 12:01:06 modelling.py [INFO] MLflow setup for DagsHub completed.
2025-07-26 12:01:06 modelling.py [INFO] Loading data from: fraud_detection_processed.csv
2025-07-26 12:01:06 modelling.py [INFO] Data loaded and split. Train: (1212, 9), Test: (304, 9)
2025-07-26 12:01:06 modelling.py [ERROR] An error occurred when training model: Cannot start run with ID d4abf271c2014cd5a3033ae2696bdc2c because active run ID does not match environment run ID. Make sure --experiment-name or --experiment-id matches experiment set with set_experiment(), or just use command-line arguments
Traceback (most recent call last):
  File "C:\Users\ACER\Documents\USU\Semester6\DBS_Journey\membangun_model_msml\MLProject\modelling.py", line 224, in main
    run_id, metrics, cv_accuracy = model_train(
                                   ~~~~~~~~~~~^
        X_train, X_test, y_train, y_test, model_name, params
        ^^^^^^^^^^^^^^^^^^^^^^^^^^^^^^^^^^^^^^^^^^^^^^^^^^^^
    )
    ^
  File "C:\Users\ACER\Documents\USU\Semester6\DBS_Journey\membangun_model_msml\MLProject\modelling.py", line 93, in model_train
    with mlflow.start_run(run_name=f'{model_name}_run_ci') as run:
         ~~~~~~~~~~~~~~~~^^^^^^^^^^^^^^^^^^^^^^^^^^^^^^^^^
  File "C:\Users\ACER\Documents\USU\Semester6\DBS_Journey\membangun_model_msml\.venv\Lib\site-packages\mlflow\tracking\fluent.py", line 374, in start_run
    raise MlflowException(
    ...<4 lines>...
    )
mlflow.exceptions.MlflowException: Cannot start run with ID d4abf271c2014cd5a3033ae2696bdc2c because active run ID does not match environment run ID. Make sure --experiment-name or --experiment-id matches experiment set with set_experiment(), or just use command-line arguments
2025-07-26 13:50:32 modelling.py [INFO] MLflow setup for DagsHub completed.
2025-07-26 13:50:32 modelling.py [INFO] Loading data from: fraud_detection_processed.csv
2025-07-26 13:50:32 modelling.py [INFO] Data loaded and split. Train: (1212, 9), Test: (304, 9)
2025-07-26 13:50:32 modelling.py [ERROR] An error occurred when training model: Cannot start run with ID 7f56bb9917d147ca9d1a9b0aac64a60b because active run ID does not match environment run ID. Make sure --experiment-name or --experiment-id matches experiment set with set_experiment(), or just use command-line arguments
Traceback (most recent call last):
  File "C:\Users\ACER\Documents\USU\Semester6\DBS_Journey\membangun_model_msml\MLProject\modelling.py", line 224, in main
    run_id, metrics, cv_accuracy = model_train(
                                   ~~~~~~~~~~~^
        X_train, X_test, y_train, y_test, model_name, params
        ^^^^^^^^^^^^^^^^^^^^^^^^^^^^^^^^^^^^^^^^^^^^^^^^^^^^
    )
    ^
  File "C:\Users\ACER\Documents\USU\Semester6\DBS_Journey\membangun_model_msml\MLProject\modelling.py", line 93, in model_train
    with mlflow.start_run(run_name=f'{model_name}_run_ci') as run:
         ~~~~~~~~~~~~~~~~^^^^^^^^^^^^^^^^^^^^^^^^^^^^^^^^^
  File "C:\Users\ACER\Documents\USU\Semester6\DBS_Journey\membangun_model_msml\.venv\Lib\site-packages\mlflow\tracking\fluent.py", line 374, in start_run
    raise MlflowException(
    ...<4 lines>...
    )
mlflow.exceptions.MlflowException: Cannot start run with ID 7f56bb9917d147ca9d1a9b0aac64a60b because active run ID does not match environment run ID. Make sure --experiment-name or --experiment-id matches experiment set with set_experiment(), or just use command-line arguments
2025-07-26 13:53:16 modelling.py [INFO] MLflow setup for DagsHub completed.
2025-07-26 13:53:16 modelling.py [INFO] Loading data from: fraud_detection_processed.csv
2025-07-26 13:53:16 modelling.py [INFO] Data loaded and split. Train: (1212, 9), Test: (304, 9)
2025-07-26 13:53:18 modelling.py [INFO] Model training started: rf. Parameters: {'n_estimators': 100, 'max_depth': 10}
2025-07-26 13:53:41 modelling.py [INFO] Model training completed.
2025-07-26 13:53:41 modelling.py [INFO] Model RandomForestClassifier(max_depth=10, random_state=42) evaluated. Accuracy: 0.9605.
2025-07-26 13:54:39 modelling.py [INFO] Cross-validation accuracy: 0.9488
2025-07-26 13:54:39 modelling.py [INFO] Metrics logged to MLflow.
2025-07-26 13:54:40 modelling.py [INFO] Confusion matrix logged as CSV and PNG to MLflow.
2025-07-26 13:54:40 modelling.py [INFO] Feature importance logged to MLflow.
2025-07-26 13:54:41 modelling.py [INFO] Metrics saved and logged to MLflow.
2025-07-26 13:54:48 modelling.py [INFO] Model artifact saved and logged to MLflow.
2025-07-26 13:54:49 modelling.py [INFO] Model rf trained and logged successfully.
2025-07-26 13:54:49 modelling.py [INFO] Run ID: 3af0e2c9fe234d8f95d77c09632580a0
2025-07-26 13:54:49 modelling.py [INFO] Accuracy: 0.9605
2025-07-26 13:54:49 modelling.py [INFO] Cross-validation accuracy: 0.9488
2025-07-26 13:54:49 modelling.py [INFO] Run ID saved to file.
2025-07-26 15:14:25 modelling.py [INFO] MLflow setup for DagsHub completed.
2025-07-26 15:14:25 modelling.py [INFO] Loading data from: fraud_detection_processed.csv
2025-07-26 15:14:25 modelling.py [INFO] Data loaded and split. Train: (1212, 9), Test: (304, 9)
2025-07-26 15:14:27 modelling.py [INFO] Model training started: rf. Parameters: {'n_estimators': 100, 'max_depth': 10}
2025-07-26 15:14:47 modelling.py [INFO] Model training completed.
2025-07-26 15:14:47 modelling.py [INFO] Model RandomForestClassifier(max_depth=10, random_state=42) evaluated. Accuracy: 0.9605.
2025-07-26 15:15:38 modelling.py [INFO] Cross-validation accuracy: 0.9488
2025-07-26 15:15:38 modelling.py [INFO] Metrics logged to MLflow.
2025-07-26 15:15:39 modelling.py [INFO] Confusion matrix logged as CSV and PNG to MLflow.
2025-07-26 15:15:40 modelling.py [INFO] Feature importance logged to MLflow.
2025-07-26 15:15:40 modelling.py [INFO] Metrics saved and logged to MLflow.
2025-07-26 15:15:48 modelling.py [INFO] Model artifact saved and logged to MLflow.
2025-07-26 15:15:48 modelling.py [INFO] Model rf trained and logged successfully.
2025-07-26 15:15:48 modelling.py [INFO] Run ID: 9bdc7c1c3b7647aa92e4fafbef6e156e
2025-07-26 15:15:48 modelling.py [INFO] Accuracy: 0.9605
2025-07-26 15:15:48 modelling.py [INFO] Cross-validation accuracy: 0.9488
2025-07-26 15:15:48 modelling.py [INFO] Run ID saved to file.
2025-07-26 15:23:11 modelling.py [INFO] MLflow setup for DagsHub completed.
2025-07-26 15:23:11 modelling.py [INFO] Loading data from: fraud_detection_processed.csv
2025-07-26 15:23:11 modelling.py [INFO] Data loaded and split. Train: (1212, 9), Test: (304, 9)
2025-07-26 15:23:13 modelling.py [INFO] Model training started: rf. Parameters: {'n_estimators': 100, 'max_depth': 10}
2025-07-26 15:23:25 modelling.py [INFO] Model training completed.
2025-07-26 15:23:25 modelling.py [INFO] Model RandomForestClassifier(max_depth=10, random_state=42) evaluated. Accuracy: 0.9605.
2025-07-26 15:24:07 modelling.py [INFO] Cross-validation accuracy: 0.9488
2025-07-26 15:24:07 modelling.py [INFO] Metrics logged to MLflow.
2025-07-26 15:24:07 modelling.py [INFO] Confusion matrix logged as CSV and PNG to MLflow.
2025-07-26 15:24:08 modelling.py [INFO] Feature importance logged to MLflow.
2025-07-26 15:24:08 modelling.py [INFO] Metrics saved and logged to MLflow.
2025-07-26 15:24:15 modelling.py [INFO] Model artifact saved and logged to MLflow.
2025-07-26 15:24:15 modelling.py [INFO] Model rf trained and logged successfully.
2025-07-26 15:24:15 modelling.py [INFO] Run ID: 7db27808d56a4a4b911c701a6bd78297
2025-07-26 15:24:15 modelling.py [INFO] Accuracy: 0.9605
2025-07-26 15:24:15 modelling.py [INFO] Cross-validation accuracy: 0.9488
2025-07-26 15:24:15 modelling.py [INFO] Run ID saved to file.
2025-07-26 15:26:14 modelling.py [INFO] MLflow setup for DagsHub completed.
2025-07-26 15:26:14 modelling.py [INFO] Loading data from: fraud_detection_processed.csv
2025-07-26 15:26:14 modelling.py [INFO] Data loaded and split. Train: (1212, 9), Test: (304, 9)
2025-07-26 15:26:16 modelling.py [INFO] Model training started: rf. Parameters: {'n_estimators': 100, 'max_depth': 10}
2025-07-26 15:26:26 modelling.py [INFO] Model training completed.
2025-07-26 15:26:26 modelling.py [INFO] Model RandomForestClassifier(max_depth=10, random_state=42) evaluated. Accuracy: 0.9605.
2025-07-26 15:26:54 modelling.py [INFO] MLflow setup for DagsHub completed.
2025-07-26 15:26:54 modelling.py [INFO] Loading data from: fraud_detection_processed.csv
2025-07-26 15:26:54 modelling.py [INFO] Data loaded and split. Train: (1212, 9), Test: (304, 9)
2025-07-26 15:26:56 modelling.py [INFO] Model training started: rf. Parameters: {'n_estimators': 100, 'max_depth': 10}
2025-07-26 15:27:05 modelling.py [INFO] Model training completed.
2025-07-26 15:27:05 modelling.py [INFO] Model RandomForestClassifier(max_depth=10, random_state=42) evaluated. Accuracy: 0.9605.
2025-07-26 15:27:50 modelling.py [INFO] Cross-validation accuracy: 0.9488
2025-07-26 15:27:50 modelling.py [INFO] Metrics logged to MLflow.
2025-07-26 15:27:51 modelling.py [INFO] Confusion matrix logged as CSV and PNG to MLflow.
2025-07-26 15:27:51 modelling.py [INFO] Feature importance logged to MLflow.
2025-07-26 15:27:51 modelling.py [INFO] Metrics saved and logged to MLflow.
2025-07-26 15:28:10 modelling.py [INFO] uri : http://localhost:5000
2025-07-26 15:28:10 modelling.py [INFO] MLflow setup for DagsHub completed.
2025-07-26 15:28:10 modelling.py [INFO] Loading data from: fraud_detection_processed.csv
2025-07-26 15:28:10 modelling.py [INFO] Data loaded and split. Train: (1212, 9), Test: (304, 9)
2025-07-26 15:28:12 modelling.py [INFO] Model training started: rf. Parameters: {'n_estimators': 100, 'max_depth': 10}
2025-07-26 15:28:23 modelling.py [INFO] Model training completed.
2025-07-26 15:28:50 modelling.py [INFO] Model RandomForestClassifier(max_depth=10, random_state=42) evaluated. Accuracy: 0.9605.
2025-07-26 15:29:22 modelling.py [INFO] uri : http://localhost:5000
2025-07-26 15:29:22 modelling.py [INFO] MLflow setup for DagsHub completed.
2025-07-26 15:29:22 modelling.py [INFO] Loading data from: fraud_detection_processed.csv
2025-07-26 15:29:22 modelling.py [INFO] Data loaded and split. Train: (1212, 9), Test: (304, 9)
2025-07-26 15:29:24 modelling.py [INFO] Model training started: rf. Parameters: {'n_estimators': 100, 'max_depth': 10}
2025-07-26 15:37:05 modelling.py [INFO] Loaded .env file from: True
2025-07-26 15:37:05 modelling.py [INFO] uri : http://localhost:5000
2025-07-26 15:37:05 modelling.py [INFO] MLflow setup for DagsHub completed.
2025-07-26 15:37:05 modelling.py [INFO] Loading data from: fraud_detection_processed.csv
2025-07-26 15:37:05 modelling.py [INFO] Data loaded and split. Train: (1212, 9), Test: (304, 9)
2025-07-26 15:37:07 modelling.py [INFO] Model training started: rf. Parameters: {'n_estimators': 100, 'max_depth': 10}
2025-07-26 15:37:15 modelling.py [INFO] Model training completed.
2025-07-26 15:38:23 modelling.py [INFO] Model RandomForestClassifier(max_depth=10, random_state=42) evaluated. Accuracy: 0.9605.
2025-07-26 15:38:58 modelling.py [INFO] Cross-validation accuracy: 0.9488
2025-07-26 15:38:58 modelling.py [INFO] Metrics logged to MLflow.
2025-07-26 15:38:59 modelling.py [INFO] Confusion matrix logged as CSV and PNG to MLflow.
2025-07-26 15:38:59 modelling.py [INFO] Feature importance logged to MLflow.
2025-07-26 15:38:59 modelling.py [INFO] Metrics saved and logged to MLflow.
2025-07-26 15:39:05 modelling.py [INFO] Model artifact saved and logged to MLflow.
2025-07-26 15:39:05 modelling.py [INFO] Model rf trained and logged successfully.
2025-07-26 15:39:05 modelling.py [INFO] Run ID: 5a13f652ee7b4a55939e06954d41f623
2025-07-26 15:39:05 modelling.py [INFO] Accuracy: 0.9605
2025-07-26 15:39:05 modelling.py [INFO] Cross-validation accuracy: 0.9488
2025-07-26 15:39:05 modelling.py [INFO] Run ID saved to file.
2025-07-26 15:41:37 modelling.py [INFO] Loaded .env file from: True
2025-07-26 15:41:37 modelling.py [INFO] uri : http://localhost:5000
2025-07-26 15:41:37 modelling.py [INFO] MLflow setup for DagsHub completed.
2025-07-26 15:41:37 modelling.py [INFO] Loading data from: fraud_detection_processed.csv
2025-07-26 15:41:37 modelling.py [INFO] Data loaded and split. Train: (1212, 9), Test: (304, 9)
2025-07-26 15:41:39 modelling.py [INFO] Model training started: rf. Parameters: {'n_estimators': 100, 'max_depth': 10}
2025-07-26 15:41:51 modelling.py [INFO] Model training completed.
2025-07-26 15:41:51 modelling.py [INFO] Model RandomForestClassifier(max_depth=10, random_state=42) evaluated. Accuracy: 0.9605.
2025-07-26 15:42:27 modelling.py [INFO] Cross-validation accuracy: 0.9488
2025-07-26 15:42:27 modelling.py [INFO] Metrics logged to MLflow.
2025-07-26 15:42:27 modelling.py [INFO] Confusion matrix logged as CSV and PNG to MLflow.
2025-07-26 15:42:27 modelling.py [INFO] Feature importance logged to MLflow.
2025-07-26 15:42:27 modelling.py [INFO] Metrics saved and logged to MLflow.
2025-07-26 15:42:32 modelling.py [INFO] Model artifact saved and logged to MLflow.
2025-07-26 15:42:34 modelling.py [INFO] Model rf trained and logged successfully.
2025-07-26 15:42:34 modelling.py [INFO] Run ID: 694d0c98eb6e48baa626c58dafb5b9a9
2025-07-26 15:42:34 modelling.py [INFO] Accuracy: 0.9605
2025-07-26 15:42:34 modelling.py [INFO] Cross-validation accuracy: 0.9488
2025-07-26 15:42:34 modelling.py [INFO] Run ID saved to file.
2025-07-26 15:48:08 modelling.py [INFO] Loaded .env file from: True
2025-07-26 15:48:08 modelling.py [INFO] Setting tracking URI to: http://localhost:5000
2025-07-26 15:48:08 modelling.py [INFO] MLflow setup completed
2025-07-26 15:48:08 modelling.py [INFO] Loading data from: fraud_detection_processed.csv
2025-07-26 15:48:08 modelling.py [INFO] Data loaded and split. Train: (1212, 9), Test: (304, 9)
2025-07-26 15:48:10 modelling.py [INFO] Model training started: rf. Parameters: {'n_estimators': 100, 'max_depth': 10}
2025-07-26 15:48:18 modelling.py [INFO] Model training completed.
2025-07-26 15:48:20 modelling.py [INFO] Model RandomForestClassifier(max_depth=10, random_state=42) evaluated. Accuracy: 0.9605.
2025-07-26 15:48:56 modelling.py [INFO] Cross-validation accuracy: 0.9488
2025-07-26 15:48:56 modelling.py [INFO] Metrics logged to MLflow.
2025-07-26 15:48:57 modelling.py [INFO] Confusion matrix logged as CSV and PNG to MLflow.
2025-07-26 15:48:57 modelling.py [INFO] Feature importance logged to MLflow.
2025-07-26 15:48:57 modelling.py [INFO] Metrics saved and logged to MLflow.
2025-07-26 15:49:04 modelling.py [INFO] Model artifact saved and logged to MLflow.
2025-07-26 15:49:04 modelling.py [INFO] Model rf trained and logged successfully.
2025-07-26 15:49:04 modelling.py [INFO] Run ID: 86c40e5283334003882eeac4c71d33e1
2025-07-26 15:49:04 modelling.py [INFO] Accuracy: 0.9605
2025-07-26 15:49:04 modelling.py [INFO] Cross-validation accuracy: 0.9488
2025-07-26 15:49:04 modelling.py [INFO] Run ID saved to file.
2025-07-26 15:50:02 modelling.py [INFO] Loaded .env file from: False
2025-07-26 15:50:02 modelling.py [INFO] Setting tracking URI to: http://localhost:5000
2025-07-26 15:50:02 modelling.py [INFO] MLflow setup completed
2025-07-26 15:50:02 modelling.py [INFO] Loading data from: fraud_detection_processed.csv
2025-07-26 15:50:02 modelling.py [INFO] Data loaded and split. Train: (1212, 9), Test: (304, 9)
2025-07-26 15:50:04 modelling.py [INFO] Model training started: rf. Parameters: {'n_estimators': 100, 'max_depth': 10}
2025-07-26 15:50:12 modelling.py [INFO] Model training completed.
2025-07-26 15:50:38 modelling.py [INFO] Model RandomForestClassifier(max_depth=10, random_state=42) evaluated. Accuracy: 0.9605.
2025-07-26 15:51:08 modelling.py [INFO] Loaded .env file from: False
2025-07-26 15:51:08 modelling.py [ERROR] MLflow setup failed: MLFLOW_TRACKING_URI must be set in environment
Traceback (most recent call last):
  File "C:\Users\ACER\Documents\USU\Semester6\DBS_Journey\membangun_model_msml\MLProject\modelling.py", line 48, in mlflow_setup
    raise ValueError('MLFLOW_TRACKING_URI must be set in environment')
ValueError: MLFLOW_TRACKING_URI must be set in environment
2025-07-26 15:51:08 modelling.py [INFO] Falling back to local MLflow tracking
2025-07-26 15:51:08 modelling.py [INFO] Loading data from: fraud_detection_processed.csv
2025-07-26 15:51:08 modelling.py [INFO] Data loaded and split. Train: (1212, 9), Test: (304, 9)
2025-07-26 15:51:08 modelling.py [INFO] Model training started: rf. Parameters: {'n_estimators': 100, 'max_depth': 10}
2025-07-26 15:51:15 modelling.py [INFO] Model training completed.
2025-07-26 15:51:15 modelling.py [INFO] Model RandomForestClassifier(max_depth=10, random_state=42) evaluated. Accuracy: 0.9605.
2025-07-26 15:51:43 modelling.py [INFO] Cross-validation accuracy: 0.9488
2025-07-26 15:52:25 modelling.py [INFO] Metrics logged to MLflow.
2025-07-26 15:52:37 modelling.py [INFO] Loaded .env file from: False
2025-07-26 15:52:37 modelling.py [INFO] Setting tracking URI to: http://localhost:5000
2025-07-26 15:52:37 modelling.py [INFO] MLflow setup completed
2025-07-26 15:52:37 modelling.py [INFO] Loading data from: fraud_detection_processed.csv
2025-07-26 15:52:37 modelling.py [INFO] Data loaded and split. Train: (1212, 9), Test: (304, 9)
2025-07-26 15:52:39 modelling.py [INFO] Model training started: rf. Parameters: {'n_estimators': 100, 'max_depth': 10}
2025-07-26 15:52:46 modelling.py [INFO] Model training completed.
2025-07-26 15:52:46 modelling.py [INFO] Model RandomForestClassifier(max_depth=10, random_state=42) evaluated. Accuracy: 0.9605.
2025-07-26 15:53:17 modelling.py [INFO] Cross-validation accuracy: 0.9488
2025-07-26 15:53:17 modelling.py [INFO] Metrics logged to MLflow.
2025-07-26 15:53:18 modelling.py [INFO] Confusion matrix logged as CSV and PNG to MLflow.
2025-07-26 15:53:18 modelling.py [INFO] Feature importance logged to MLflow.
2025-07-26 15:53:18 modelling.py [INFO] Metrics saved and logged to MLflow.
2025-07-26 15:53:23 modelling.py [INFO] Model artifact saved and logged to MLflow.
2025-07-26 15:53:23 modelling.py [INFO] Model rf trained and logged successfully.
2025-07-26 15:53:23 modelling.py [INFO] Run ID: 062400c2da9d4ffcb3b327c75b78d7f2
2025-07-26 15:53:23 modelling.py [INFO] Accuracy: 0.9605
2025-07-26 15:53:23 modelling.py [INFO] Cross-validation accuracy: 0.9488
2025-07-26 15:53:23 modelling.py [INFO] Run ID saved to file.
2025-07-26 15:54:03 modelling.py [INFO] Loaded .env file from: False
2025-07-26 15:54:03 modelling.py [INFO] Setting tracking URI to: http://localhost:5000
2025-07-26 15:54:03 modelling.py [INFO] MLflow setup completed
2025-07-26 15:54:03 modelling.py [INFO] Loading data from: fraud_detection_processed.csv
2025-07-26 15:54:03 modelling.py [INFO] Data loaded and split. Train: (1212, 9), Test: (304, 9)
2025-07-26 15:54:04 modelling.py [ERROR] An error occurred when training model: API request to endpoint /api/2.0/mlflow/runs/get failed with error code 404 != 200. Response body: ''
Traceback (most recent call last):
  File "C:\Users\ACER\Documents\USU\Semester6\DBS_Journey\membangun_model_msml\MLProject\modelling.py", line 225, in main
    run_id, metrics, cv_accuracy = model_train(
                                   ~~~~~~~~~~~^
        X_train, X_test, y_train, y_test, model_name, params
        ^^^^^^^^^^^^^^^^^^^^^^^^^^^^^^^^^^^^^^^^^^^^^^^^^^^^
    )
    ^
  File "C:\Users\ACER\Documents\USU\Semester6\DBS_Journey\membangun_model_msml\MLProject\modelling.py", line 94, in model_train
    with mlflow.start_run(run_name=f'{model_name}_run_ci') as run:
         ~~~~~~~~~~~~~~~~^^^^^^^^^^^^^^^^^^^^^^^^^^^^^^^^^
  File "C:\Users\ACER\Documents\USU\Semester6\DBS_Journey\membangun_model_msml\.venv\Lib\site-packages\mlflow\tracking\fluent.py", line 368, in start_run
    active_run_obj = client.get_run(existing_run_id)
  File "C:\Users\ACER\Documents\USU\Semester6\DBS_Journey\membangun_model_msml\.venv\Lib\site-packages\mlflow\tracking\client.py", line 226, in get_run
    return self._tracking_client.get_run(run_id)
           ~~~~~~~~~~~~~~~~~~~~~~~~~~~~~^^^^^^^^
  File "C:\Users\ACER\Documents\USU\Semester6\DBS_Journey\membangun_model_msml\.venv\Lib\site-packages\mlflow\tracking\_tracking_service\client.py", line 106, in get_run
    return self.store.get_run(run_id)
           ~~~~~~~~~~~~~~~~~~^^^^^^^^
  File "C:\Users\ACER\Documents\USU\Semester6\DBS_Journey\membangun_model_msml\.venv\Lib\site-packages\mlflow\store\tracking\rest_store.py", line 169, in get_run
    response_proto = self._call_endpoint(GetRun, req_body)
  File "C:\Users\ACER\Documents\USU\Semester6\DBS_Journey\membangun_model_msml\.venv\Lib\site-packages\mlflow\store\tracking\rest_store.py", line 82, in _call_endpoint
    return call_endpoint(self.get_host_creds(), endpoint, method, json_body, response_proto)
  File "C:\Users\ACER\Documents\USU\Semester6\DBS_Journey\membangun_model_msml\.venv\Lib\site-packages\mlflow\utils\rest_utils.py", line 370, in call_endpoint
    response = verify_rest_response(response, endpoint)
  File "C:\Users\ACER\Documents\USU\Semester6\DBS_Journey\membangun_model_msml\.venv\Lib\site-packages\mlflow\utils\rest_utils.py", line 246, in verify_rest_response
    raise MlflowException(
    ...<2 lines>...
    )
mlflow.exceptions.MlflowException: API request to endpoint /api/2.0/mlflow/runs/get failed with error code 404 != 200. Response body: ''
2025-07-26 15:56:30 modelling.py [INFO] Loaded .env file from: False
2025-07-26 15:56:30 modelling.py [INFO] Setting tracking URI to: https://dagshub.com/Rafaellsimarmata/workflow-CI-Rafael-Simarmata.mlflow
2025-07-26 15:56:30 modelling.py [INFO] MLflow setup completed
2025-07-26 15:56:30 modelling.py [INFO] Loading data from: fraud_detection_processed.csv
2025-07-26 15:56:30 modelling.py [INFO] Data loaded and split. Train: (1212, 9), Test: (304, 9)
2025-07-26 15:57:34 modelling.py [ERROR] An error occurred when training model: API request to https://dagshub.com/Rafaellsimarmata/workflow-CI-Rafael-Simarmata.mlflow/api/2.0/mlflow/runs/get failed with exception HTTPSConnectionPool(host='dagshub.com', port=443): Max retries exceeded with url: /Rafaellsimarmata/workflow-CI-Rafael-Simarmata.mlflow/api/2.0/mlflow/runs/get?run_uuid=e75e1f81dce24ee69aef691cf4738459&run_id=e75e1f81dce24ee69aef691cf4738459 (Caused by ResponseError('too many 500 error responses'))
urllib3.exceptions.ResponseError: too many 500 error responses

The above exception was the direct cause of the following exception:

Traceback (most recent call last):
  File "C:\Users\ACER\Documents\USU\Semester6\DBS_Journey\membangun_model_msml\.venv\Lib\site-packages\requests\adapters.py", line 667, in send
    resp = conn.urlopen(
        method=request.method,
    ...<9 lines>...
        chunked=chunked,
    )
  File "C:\Users\ACER\Documents\USU\Semester6\DBS_Journey\membangun_model_msml\.venv\Lib\site-packages\urllib3\connectionpool.py", line 942, in urlopen
    return self.urlopen(
           ~~~~~~~~~~~~^
        method,
        ^^^^^^^
    ...<13 lines>...
        **response_kw,
        ^^^^^^^^^^^^^^
    )
    ^
  File "C:\Users\ACER\Documents\USU\Semester6\DBS_Journey\membangun_model_msml\.venv\Lib\site-packages\urllib3\connectionpool.py", line 942, in urlopen
    return self.urlopen(
           ~~~~~~~~~~~~^
        method,
        ^^^^^^^
    ...<13 lines>...
        **response_kw,
        ^^^^^^^^^^^^^^
    )
    ^
  File "C:\Users\ACER\Documents\USU\Semester6\DBS_Journey\membangun_model_msml\.venv\Lib\site-packages\urllib3\connectionpool.py", line 942, in urlopen
    return self.urlopen(
           ~~~~~~~~~~~~^
        method,
        ^^^^^^^
    ...<13 lines>...
        **response_kw,
        ^^^^^^^^^^^^^^
    )
    ^
  [Previous line repeated 2 more times]
  File "C:\Users\ACER\Documents\USU\Semester6\DBS_Journey\membangun_model_msml\.venv\Lib\site-packages\urllib3\connectionpool.py", line 932, in urlopen
    retries = retries.increment(method, url, response=response, _pool=self)
  File "C:\Users\ACER\Documents\USU\Semester6\DBS_Journey\membangun_model_msml\.venv\Lib\site-packages\urllib3\util\retry.py", line 519, in increment
    raise MaxRetryError(_pool, url, reason) from reason  # type: ignore[arg-type]
    ^^^^^^^^^^^^^^^^^^^^^^^^^^^^^^^^^^^^^^^^^^^^^^^^^^^
urllib3.exceptions.MaxRetryError: HTTPSConnectionPool(host='dagshub.com', port=443): Max retries exceeded with url: /Rafaellsimarmata/workflow-CI-Rafael-Simarmata.mlflow/api/2.0/mlflow/runs/get?run_uuid=e75e1f81dce24ee69aef691cf4738459&run_id=e75e1f81dce24ee69aef691cf4738459 (Caused by ResponseError('too many 500 error responses'))

During handling of the above exception, another exception occurred:

Traceback (most recent call last):
  File "C:\Users\ACER\Documents\USU\Semester6\DBS_Journey\membangun_model_msml\.venv\Lib\site-packages\mlflow\utils\rest_utils.py", line 189, in http_request
    return _get_http_response_with_retries(
        method,
    ...<10 lines>...
        **kwargs,
    )
  File "C:\Users\ACER\Documents\USU\Semester6\DBS_Journey\membangun_model_msml\.venv\Lib\site-packages\mlflow\utils\request_utils.py", line 237, in _get_http_response_with_retries
    return session.request(method, url, allow_redirects=allow_redirects, **kwargs)
           ~~~~~~~~~~~~~~~^^^^^^^^^^^^^^^^^^^^^^^^^^^^^^^^^^^^^^^^^^^^^^^^^^^^^^^^
  File "C:\Users\ACER\Documents\USU\Semester6\DBS_Journey\membangun_model_msml\.venv\Lib\site-packages\requests\sessions.py", line 589, in request
    resp = self.send(prep, **send_kwargs)
  File "C:\Users\ACER\Documents\USU\Semester6\DBS_Journey\membangun_model_msml\.venv\Lib\site-packages\requests\sessions.py", line 703, in send
    r = adapter.send(request, **kwargs)
  File "C:\Users\ACER\Documents\USU\Semester6\DBS_Journey\membangun_model_msml\.venv\Lib\site-packages\requests\adapters.py", line 691, in send
    raise RetryError(e, request=request)
requests.exceptions.RetryError: HTTPSConnectionPool(host='dagshub.com', port=443): Max retries exceeded with url: /Rafaellsimarmata/workflow-CI-Rafael-Simarmata.mlflow/api/2.0/mlflow/runs/get?run_uuid=e75e1f81dce24ee69aef691cf4738459&run_id=e75e1f81dce24ee69aef691cf4738459 (Caused by ResponseError('too many 500 error responses'))

During handling of the above exception, another exception occurred:

Traceback (most recent call last):
  File "C:\Users\ACER\Documents\USU\Semester6\DBS_Journey\membangun_model_msml\MLProject\modelling.py", line 228, in main
    run_id, metrics, cv_accuracy = model_train(
                                   ~~~~~~~~~~~^
        X_train, X_test, y_train, y_test, model_name, params
        ^^^^^^^^^^^^^^^^^^^^^^^^^^^^^^^^^^^^^^^^^^^^^^^^^^^^
    )
    ^
  File "C:\Users\ACER\Documents\USU\Semester6\DBS_Journey\membangun_model_msml\MLProject\modelling.py", line 97, in model_train
    with mlflow.start_run(run_name=f'{model_name}_run_ci') as run:
         ~~~~~~~~~~~~~~~~^^^^^^^^^^^^^^^^^^^^^^^^^^^^^^^^^
  File "C:\Users\ACER\Documents\USU\Semester6\DBS_Journey\membangun_model_msml\.venv\Lib\site-packages\mlflow\tracking\fluent.py", line 368, in start_run
    active_run_obj = client.get_run(existing_run_id)
  File "C:\Users\ACER\Documents\USU\Semester6\DBS_Journey\membangun_model_msml\.venv\Lib\site-packages\mlflow\tracking\client.py", line 226, in get_run
    return self._tracking_client.get_run(run_id)
           ~~~~~~~~~~~~~~~~~~~~~~~~~~~~~^^^^^^^^
  File "C:\Users\ACER\Documents\USU\Semester6\DBS_Journey\membangun_model_msml\.venv\Lib\site-packages\mlflow\tracking\_tracking_service\client.py", line 106, in get_run
    return self.store.get_run(run_id)
           ~~~~~~~~~~~~~~~~~~^^^^^^^^
  File "C:\Users\ACER\Documents\USU\Semester6\DBS_Journey\membangun_model_msml\.venv\Lib\site-packages\mlflow\store\tracking\rest_store.py", line 169, in get_run
    response_proto = self._call_endpoint(GetRun, req_body)
  File "C:\Users\ACER\Documents\USU\Semester6\DBS_Journey\membangun_model_msml\.venv\Lib\site-packages\mlflow\store\tracking\rest_store.py", line 82, in _call_endpoint
    return call_endpoint(self.get_host_creds(), endpoint, method, json_body, response_proto)
  File "C:\Users\ACER\Documents\USU\Semester6\DBS_Journey\membangun_model_msml\.venv\Lib\site-packages\mlflow\utils\rest_utils.py", line 365, in call_endpoint
    response = http_request(**call_kwargs)
  File "C:\Users\ACER\Documents\USU\Semester6\DBS_Journey\membangun_model_msml\.venv\Lib\site-packages\mlflow\utils\rest_utils.py", line 212, in http_request
    raise MlflowException(f"API request to {url} failed with exception {e}")
mlflow.exceptions.MlflowException: API request to https://dagshub.com/Rafaellsimarmata/workflow-CI-Rafael-Simarmata.mlflow/api/2.0/mlflow/runs/get failed with exception HTTPSConnectionPool(host='dagshub.com', port=443): Max retries exceeded with url: /Rafaellsimarmata/workflow-CI-Rafael-Simarmata.mlflow/api/2.0/mlflow/runs/get?run_uuid=e75e1f81dce24ee69aef691cf4738459&run_id=e75e1f81dce24ee69aef691cf4738459 (Caused by ResponseError('too many 500 error responses'))
2025-07-26 15:58:45 modelling.py [INFO] Loaded .env file from: False
2025-07-26 15:58:45 modelling.py [INFO] Setting tracking URI to: https://dagshub.com/Rafaellsimarmata/workflow-CI-Rafael-Simarmata.mlflow
2025-07-26 15:58:45 modelling.py [INFO] MLflow setup completed
2025-07-26 15:58:45 modelling.py [INFO] Loading data from: fraud_detection_processed.csv
2025-07-26 15:58:45 modelling.py [INFO] Data loaded and split. Train: (1212, 9), Test: (304, 9)
2025-07-26 15:59:50 modelling.py [ERROR] An error occurred when training model: API request to https://dagshub.com/Rafaellsimarmata/workflow-CI-Rafael-Simarmata.mlflow/api/2.0/mlflow/runs/get failed with exception HTTPSConnectionPool(host='dagshub.com', port=443): Max retries exceeded with url: /Rafaellsimarmata/workflow-CI-Rafael-Simarmata.mlflow/api/2.0/mlflow/runs/get?run_uuid=b83f1248a7b543c9a559f852f9ae3084&run_id=b83f1248a7b543c9a559f852f9ae3084 (Caused by ResponseError('too many 500 error responses'))
urllib3.exceptions.ResponseError: too many 500 error responses

The above exception was the direct cause of the following exception:

Traceback (most recent call last):
  File "C:\Users\ACER\Documents\USU\Semester6\DBS_Journey\membangun_model_msml\.venv\Lib\site-packages\requests\adapters.py", line 667, in send
    resp = conn.urlopen(
        method=request.method,
    ...<9 lines>...
        chunked=chunked,
    )
  File "C:\Users\ACER\Documents\USU\Semester6\DBS_Journey\membangun_model_msml\.venv\Lib\site-packages\urllib3\connectionpool.py", line 942, in urlopen
    return self.urlopen(
           ~~~~~~~~~~~~^
        method,
        ^^^^^^^
    ...<13 lines>...
        **response_kw,
        ^^^^^^^^^^^^^^
    )
    ^
  File "C:\Users\ACER\Documents\USU\Semester6\DBS_Journey\membangun_model_msml\.venv\Lib\site-packages\urllib3\connectionpool.py", line 942, in urlopen
    return self.urlopen(
           ~~~~~~~~~~~~^
        method,
        ^^^^^^^
    ...<13 lines>...
        **response_kw,
        ^^^^^^^^^^^^^^
    )
    ^
  File "C:\Users\ACER\Documents\USU\Semester6\DBS_Journey\membangun_model_msml\.venv\Lib\site-packages\urllib3\connectionpool.py", line 942, in urlopen
    return self.urlopen(
           ~~~~~~~~~~~~^
        method,
        ^^^^^^^
    ...<13 lines>...
        **response_kw,
        ^^^^^^^^^^^^^^
    )
    ^
  [Previous line repeated 2 more times]
  File "C:\Users\ACER\Documents\USU\Semester6\DBS_Journey\membangun_model_msml\.venv\Lib\site-packages\urllib3\connectionpool.py", line 932, in urlopen
    retries = retries.increment(method, url, response=response, _pool=self)
  File "C:\Users\ACER\Documents\USU\Semester6\DBS_Journey\membangun_model_msml\.venv\Lib\site-packages\urllib3\util\retry.py", line 519, in increment
    raise MaxRetryError(_pool, url, reason) from reason  # type: ignore[arg-type]
    ^^^^^^^^^^^^^^^^^^^^^^^^^^^^^^^^^^^^^^^^^^^^^^^^^^^
urllib3.exceptions.MaxRetryError: HTTPSConnectionPool(host='dagshub.com', port=443): Max retries exceeded with url: /Rafaellsimarmata/workflow-CI-Rafael-Simarmata.mlflow/api/2.0/mlflow/runs/get?run_uuid=b83f1248a7b543c9a559f852f9ae3084&run_id=b83f1248a7b543c9a559f852f9ae3084 (Caused by ResponseError('too many 500 error responses'))

During handling of the above exception, another exception occurred:

Traceback (most recent call last):
  File "C:\Users\ACER\Documents\USU\Semester6\DBS_Journey\membangun_model_msml\.venv\Lib\site-packages\mlflow\utils\rest_utils.py", line 189, in http_request
    return _get_http_response_with_retries(
        method,
    ...<10 lines>...
        **kwargs,
    )
  File "C:\Users\ACER\Documents\USU\Semester6\DBS_Journey\membangun_model_msml\.venv\Lib\site-packages\mlflow\utils\request_utils.py", line 237, in _get_http_response_with_retries
    return session.request(method, url, allow_redirects=allow_redirects, **kwargs)
           ~~~~~~~~~~~~~~~^^^^^^^^^^^^^^^^^^^^^^^^^^^^^^^^^^^^^^^^^^^^^^^^^^^^^^^^
  File "C:\Users\ACER\Documents\USU\Semester6\DBS_Journey\membangun_model_msml\.venv\Lib\site-packages\requests\sessions.py", line 589, in request
    resp = self.send(prep, **send_kwargs)
  File "C:\Users\ACER\Documents\USU\Semester6\DBS_Journey\membangun_model_msml\.venv\Lib\site-packages\requests\sessions.py", line 703, in send
    r = adapter.send(request, **kwargs)
  File "C:\Users\ACER\Documents\USU\Semester6\DBS_Journey\membangun_model_msml\.venv\Lib\site-packages\requests\adapters.py", line 691, in send
    raise RetryError(e, request=request)
requests.exceptions.RetryError: HTTPSConnectionPool(host='dagshub.com', port=443): Max retries exceeded with url: /Rafaellsimarmata/workflow-CI-Rafael-Simarmata.mlflow/api/2.0/mlflow/runs/get?run_uuid=b83f1248a7b543c9a559f852f9ae3084&run_id=b83f1248a7b543c9a559f852f9ae3084 (Caused by ResponseError('too many 500 error responses'))

During handling of the above exception, another exception occurred:

Traceback (most recent call last):
  File "C:\Users\ACER\Documents\USU\Semester6\DBS_Journey\membangun_model_msml\MLProject\modelling.py", line 228, in main
    run_id, metrics, cv_accuracy = model_train(
                                   ~~~~~~~~~~~^
        X_train, X_test, y_train, y_test, model_name, params
        ^^^^^^^^^^^^^^^^^^^^^^^^^^^^^^^^^^^^^^^^^^^^^^^^^^^^
    )
    ^
  File "C:\Users\ACER\Documents\USU\Semester6\DBS_Journey\membangun_model_msml\MLProject\modelling.py", line 97, in model_train
    with mlflow.start_run(run_name=f'{model_name}_run_ci') as run:
         ~~~~~~~~~~~~~~~~^^^^^^^^^^^^^^^^^^^^^^^^^^^^^^^^^
  File "C:\Users\ACER\Documents\USU\Semester6\DBS_Journey\membangun_model_msml\.venv\Lib\site-packages\mlflow\tracking\fluent.py", line 368, in start_run
    active_run_obj = client.get_run(existing_run_id)
  File "C:\Users\ACER\Documents\USU\Semester6\DBS_Journey\membangun_model_msml\.venv\Lib\site-packages\mlflow\tracking\client.py", line 226, in get_run
    return self._tracking_client.get_run(run_id)
           ~~~~~~~~~~~~~~~~~~~~~~~~~~~~~^^^^^^^^
  File "C:\Users\ACER\Documents\USU\Semester6\DBS_Journey\membangun_model_msml\.venv\Lib\site-packages\mlflow\tracking\_tracking_service\client.py", line 106, in get_run
    return self.store.get_run(run_id)
           ~~~~~~~~~~~~~~~~~~^^^^^^^^
  File "C:\Users\ACER\Documents\USU\Semester6\DBS_Journey\membangun_model_msml\.venv\Lib\site-packages\mlflow\store\tracking\rest_store.py", line 169, in get_run
    response_proto = self._call_endpoint(GetRun, req_body)
  File "C:\Users\ACER\Documents\USU\Semester6\DBS_Journey\membangun_model_msml\.venv\Lib\site-packages\mlflow\store\tracking\rest_store.py", line 82, in _call_endpoint
    return call_endpoint(self.get_host_creds(), endpoint, method, json_body, response_proto)
  File "C:\Users\ACER\Documents\USU\Semester6\DBS_Journey\membangun_model_msml\.venv\Lib\site-packages\mlflow\utils\rest_utils.py", line 365, in call_endpoint
    response = http_request(**call_kwargs)
  File "C:\Users\ACER\Documents\USU\Semester6\DBS_Journey\membangun_model_msml\.venv\Lib\site-packages\mlflow\utils\rest_utils.py", line 212, in http_request
    raise MlflowException(f"API request to {url} failed with exception {e}")
mlflow.exceptions.MlflowException: API request to https://dagshub.com/Rafaellsimarmata/workflow-CI-Rafael-Simarmata.mlflow/api/2.0/mlflow/runs/get failed with exception HTTPSConnectionPool(host='dagshub.com', port=443): Max retries exceeded with url: /Rafaellsimarmata/workflow-CI-Rafael-Simarmata.mlflow/api/2.0/mlflow/runs/get?run_uuid=b83f1248a7b543c9a559f852f9ae3084&run_id=b83f1248a7b543c9a559f852f9ae3084 (Caused by ResponseError('too many 500 error responses'))
2025-07-26 16:01:36 modelling.py [INFO] Loaded .env file from: False
2025-07-26 16:01:36 modelling.py [INFO] Setting tracking URI to: https://dagshub.com/Rafaellsimarmata/workflow-CI-Rafael-Simarmata.mlflow
2025-07-26 16:01:36 modelling.py [INFO] MLflow setup completed
2025-07-26 16:01:36 modelling.py [INFO] Loading data from: fraud_detection_processed.csv
2025-07-26 16:01:36 modelling.py [INFO] Data loaded and split. Train: (1212, 9), Test: (304, 9)
2025-07-26 16:02:07 modelling.py [INFO] Loaded .env file from: False
2025-07-26 16:02:07 modelling.py [INFO] Setting tracking URI to: https://dagshub.com/Rafaellsimarmata/workflow-CI-Rafael-Simarmata.mlflow
2025-07-26 16:02:07 modelling.py [INFO] MLflow setup completed
2025-07-26 16:02:07 modelling.py [INFO] Loading data from: fraud_detection_processed.csv
2025-07-26 16:02:07 modelling.py [INFO] Data loaded and split. Train: (1212, 9), Test: (304, 9)
2025-07-26 16:04:54 modelling.py [INFO] Loaded .env file from: False
2025-07-26 16:04:54 modelling.py [INFO] Setting tracking URI to: https://dagshub.com/Rafaellsimarmata/workflow-CI-Rafael-Simarmata.mlflow
2025-07-26 16:04:54 modelling.py [INFO] MLflow setup completed
2025-07-26 16:04:54 modelling.py [INFO] Loading data from: fraud_detection_processed.csv
2025-07-26 16:04:54 modelling.py [INFO] Data loaded and split. Train: (1212, 9), Test: (304, 9)
2025-07-26 16:05:58 modelling.py [ERROR] An error occurred when training model: API request to https://dagshub.com/Rafaellsimarmata/workflow-CI-Rafael-Simarmata.mlflow/api/2.0/mlflow/runs/get failed with exception HTTPSConnectionPool(host='dagshub.com', port=443): Max retries exceeded with url: /Rafaellsimarmata/workflow-CI-Rafael-Simarmata.mlflow/api/2.0/mlflow/runs/get?run_uuid=72e97cb350af497688436f4ed60f6a62&run_id=72e97cb350af497688436f4ed60f6a62 (Caused by ResponseError('too many 500 error responses'))
urllib3.exceptions.ResponseError: too many 500 error responses

The above exception was the direct cause of the following exception:

Traceback (most recent call last):
  File "C:\Users\ACER\Documents\USU\Semester6\DBS_Journey\membangun_model_msml\.venv\Lib\site-packages\requests\adapters.py", line 667, in send
    resp = conn.urlopen(
        method=request.method,
    ...<9 lines>...
        chunked=chunked,
    )
  File "C:\Users\ACER\Documents\USU\Semester6\DBS_Journey\membangun_model_msml\.venv\Lib\site-packages\urllib3\connectionpool.py", line 942, in urlopen
    return self.urlopen(
           ~~~~~~~~~~~~^
        method,
        ^^^^^^^
    ...<13 lines>...
        **response_kw,
        ^^^^^^^^^^^^^^
    )
    ^
  File "C:\Users\ACER\Documents\USU\Semester6\DBS_Journey\membangun_model_msml\.venv\Lib\site-packages\urllib3\connectionpool.py", line 942, in urlopen
    return self.urlopen(
           ~~~~~~~~~~~~^
        method,
        ^^^^^^^
    ...<13 lines>...
        **response_kw,
        ^^^^^^^^^^^^^^
    )
    ^
  File "C:\Users\ACER\Documents\USU\Semester6\DBS_Journey\membangun_model_msml\.venv\Lib\site-packages\urllib3\connectionpool.py", line 942, in urlopen
    return self.urlopen(
           ~~~~~~~~~~~~^
        method,
        ^^^^^^^
    ...<13 lines>...
        **response_kw,
        ^^^^^^^^^^^^^^
    )
    ^
  [Previous line repeated 2 more times]
  File "C:\Users\ACER\Documents\USU\Semester6\DBS_Journey\membangun_model_msml\.venv\Lib\site-packages\urllib3\connectionpool.py", line 932, in urlopen
    retries = retries.increment(method, url, response=response, _pool=self)
  File "C:\Users\ACER\Documents\USU\Semester6\DBS_Journey\membangun_model_msml\.venv\Lib\site-packages\urllib3\util\retry.py", line 519, in increment
    raise MaxRetryError(_pool, url, reason) from reason  # type: ignore[arg-type]
    ^^^^^^^^^^^^^^^^^^^^^^^^^^^^^^^^^^^^^^^^^^^^^^^^^^^
urllib3.exceptions.MaxRetryError: HTTPSConnectionPool(host='dagshub.com', port=443): Max retries exceeded with url: /Rafaellsimarmata/workflow-CI-Rafael-Simarmata.mlflow/api/2.0/mlflow/runs/get?run_uuid=72e97cb350af497688436f4ed60f6a62&run_id=72e97cb350af497688436f4ed60f6a62 (Caused by ResponseError('too many 500 error responses'))

During handling of the above exception, another exception occurred:

Traceback (most recent call last):
  File "C:\Users\ACER\Documents\USU\Semester6\DBS_Journey\membangun_model_msml\.venv\Lib\site-packages\mlflow\utils\rest_utils.py", line 189, in http_request
    return _get_http_response_with_retries(
        method,
    ...<10 lines>...
        **kwargs,
    )
  File "C:\Users\ACER\Documents\USU\Semester6\DBS_Journey\membangun_model_msml\.venv\Lib\site-packages\mlflow\utils\request_utils.py", line 237, in _get_http_response_with_retries
    return session.request(method, url, allow_redirects=allow_redirects, **kwargs)
           ~~~~~~~~~~~~~~~^^^^^^^^^^^^^^^^^^^^^^^^^^^^^^^^^^^^^^^^^^^^^^^^^^^^^^^^
  File "C:\Users\ACER\Documents\USU\Semester6\DBS_Journey\membangun_model_msml\.venv\Lib\site-packages\requests\sessions.py", line 589, in request
    resp = self.send(prep, **send_kwargs)
  File "C:\Users\ACER\Documents\USU\Semester6\DBS_Journey\membangun_model_msml\.venv\Lib\site-packages\requests\sessions.py", line 703, in send
    r = adapter.send(request, **kwargs)
  File "C:\Users\ACER\Documents\USU\Semester6\DBS_Journey\membangun_model_msml\.venv\Lib\site-packages\requests\adapters.py", line 691, in send
    raise RetryError(e, request=request)
requests.exceptions.RetryError: HTTPSConnectionPool(host='dagshub.com', port=443): Max retries exceeded with url: /Rafaellsimarmata/workflow-CI-Rafael-Simarmata.mlflow/api/2.0/mlflow/runs/get?run_uuid=72e97cb350af497688436f4ed60f6a62&run_id=72e97cb350af497688436f4ed60f6a62 (Caused by ResponseError('too many 500 error responses'))

During handling of the above exception, another exception occurred:

Traceback (most recent call last):
  File "C:\Users\ACER\Documents\USU\Semester6\DBS_Journey\membangun_model_msml\MLProject\modelling.py", line 227, in main
    run_id, metrics, cv_accuracy = model_train(
                                   ~~~~~~~~~~~^
        X_train, X_test, y_train, y_test, model_name, params
        ^^^^^^^^^^^^^^^^^^^^^^^^^^^^^^^^^^^^^^^^^^^^^^^^^^^^
    )
    ^
  File "C:\Users\ACER\Documents\USU\Semester6\DBS_Journey\membangun_model_msml\MLProject\modelling.py", line 96, in model_train
    with mlflow.start_run(run_name=f'{model_name}_run_ci') as run:
         ~~~~~~~~~~~~~~~~^^^^^^^^^^^^^^^^^^^^^^^^^^^^^^^^^
  File "C:\Users\ACER\Documents\USU\Semester6\DBS_Journey\membangun_model_msml\.venv\Lib\site-packages\mlflow\tracking\fluent.py", line 368, in start_run
    active_run_obj = client.get_run(existing_run_id)
  File "C:\Users\ACER\Documents\USU\Semester6\DBS_Journey\membangun_model_msml\.venv\Lib\site-packages\mlflow\tracking\client.py", line 226, in get_run
    return self._tracking_client.get_run(run_id)
           ~~~~~~~~~~~~~~~~~~~~~~~~~~~~~^^^^^^^^
  File "C:\Users\ACER\Documents\USU\Semester6\DBS_Journey\membangun_model_msml\.venv\Lib\site-packages\mlflow\tracking\_tracking_service\client.py", line 106, in get_run
    return self.store.get_run(run_id)
           ~~~~~~~~~~~~~~~~~~^^^^^^^^
  File "C:\Users\ACER\Documents\USU\Semester6\DBS_Journey\membangun_model_msml\.venv\Lib\site-packages\mlflow\store\tracking\rest_store.py", line 169, in get_run
    response_proto = self._call_endpoint(GetRun, req_body)
  File "C:\Users\ACER\Documents\USU\Semester6\DBS_Journey\membangun_model_msml\.venv\Lib\site-packages\mlflow\store\tracking\rest_store.py", line 82, in _call_endpoint
    return call_endpoint(self.get_host_creds(), endpoint, method, json_body, response_proto)
  File "C:\Users\ACER\Documents\USU\Semester6\DBS_Journey\membangun_model_msml\.venv\Lib\site-packages\mlflow\utils\rest_utils.py", line 365, in call_endpoint
    response = http_request(**call_kwargs)
  File "C:\Users\ACER\Documents\USU\Semester6\DBS_Journey\membangun_model_msml\.venv\Lib\site-packages\mlflow\utils\rest_utils.py", line 212, in http_request
    raise MlflowException(f"API request to {url} failed with exception {e}")
mlflow.exceptions.MlflowException: API request to https://dagshub.com/Rafaellsimarmata/workflow-CI-Rafael-Simarmata.mlflow/api/2.0/mlflow/runs/get failed with exception HTTPSConnectionPool(host='dagshub.com', port=443): Max retries exceeded with url: /Rafaellsimarmata/workflow-CI-Rafael-Simarmata.mlflow/api/2.0/mlflow/runs/get?run_uuid=72e97cb350af497688436f4ed60f6a62&run_id=72e97cb350af497688436f4ed60f6a62 (Caused by ResponseError('too many 500 error responses'))
2025-07-26 16:31:22 modelling.py [INFO] Loaded .env file from: True
2025-07-26 16:31:22 modelling.py [INFO] Setting tracking URI to: https://dagshub.com/Rafaellsimarmata/workflow-CI-Rafael-Simarmata.mlflow
2025-07-26 16:31:22 modelling.py [INFO] MLflow setup completed
2025-07-26 16:31:22 modelling.py [INFO] Loading data from: fraud_detection_processed.csv
2025-07-26 16:31:22 modelling.py [INFO] Data loaded and split. Train: (1212, 9), Test: (304, 9)
2025-07-26 16:32:27 modelling.py [ERROR] An error occurred when training model: API request to https://dagshub.com/Rafaellsimarmata/workflow-CI-Rafael-Simarmata.mlflow/api/2.0/mlflow/runs/get failed with exception HTTPSConnectionPool(host='dagshub.com', port=443): Max retries exceeded with url: /Rafaellsimarmata/workflow-CI-Rafael-Simarmata.mlflow/api/2.0/mlflow/runs/get?run_uuid=685010e5c60e422c8d1d111c9f2d76a1&run_id=685010e5c60e422c8d1d111c9f2d76a1 (Caused by ResponseError('too many 500 error responses'))
urllib3.exceptions.ResponseError: too many 500 error responses

The above exception was the direct cause of the following exception:

Traceback (most recent call last):
  File "C:\Users\ACER\Documents\USU\Semester6\DBS_Journey\membangun_model_msml\.venv\Lib\site-packages\requests\adapters.py", line 667, in send
    resp = conn.urlopen(
        method=request.method,
    ...<9 lines>...
        chunked=chunked,
    )
  File "C:\Users\ACER\Documents\USU\Semester6\DBS_Journey\membangun_model_msml\.venv\Lib\site-packages\urllib3\connectionpool.py", line 942, in urlopen
    return self.urlopen(
           ~~~~~~~~~~~~^
        method,
        ^^^^^^^
    ...<13 lines>...
        **response_kw,
        ^^^^^^^^^^^^^^
    )
    ^
  File "C:\Users\ACER\Documents\USU\Semester6\DBS_Journey\membangun_model_msml\.venv\Lib\site-packages\urllib3\connectionpool.py", line 942, in urlopen
    return self.urlopen(
           ~~~~~~~~~~~~^
        method,
        ^^^^^^^
    ...<13 lines>...
        **response_kw,
        ^^^^^^^^^^^^^^
    )
    ^
  File "C:\Users\ACER\Documents\USU\Semester6\DBS_Journey\membangun_model_msml\.venv\Lib\site-packages\urllib3\connectionpool.py", line 942, in urlopen
    return self.urlopen(
           ~~~~~~~~~~~~^
        method,
        ^^^^^^^
    ...<13 lines>...
        **response_kw,
        ^^^^^^^^^^^^^^
    )
    ^
  [Previous line repeated 2 more times]
  File "C:\Users\ACER\Documents\USU\Semester6\DBS_Journey\membangun_model_msml\.venv\Lib\site-packages\urllib3\connectionpool.py", line 932, in urlopen
    retries = retries.increment(method, url, response=response, _pool=self)
  File "C:\Users\ACER\Documents\USU\Semester6\DBS_Journey\membangun_model_msml\.venv\Lib\site-packages\urllib3\util\retry.py", line 519, in increment
    raise MaxRetryError(_pool, url, reason) from reason  # type: ignore[arg-type]
    ^^^^^^^^^^^^^^^^^^^^^^^^^^^^^^^^^^^^^^^^^^^^^^^^^^^
urllib3.exceptions.MaxRetryError: HTTPSConnectionPool(host='dagshub.com', port=443): Max retries exceeded with url: /Rafaellsimarmata/workflow-CI-Rafael-Simarmata.mlflow/api/2.0/mlflow/runs/get?run_uuid=685010e5c60e422c8d1d111c9f2d76a1&run_id=685010e5c60e422c8d1d111c9f2d76a1 (Caused by ResponseError('too many 500 error responses'))

During handling of the above exception, another exception occurred:

Traceback (most recent call last):
  File "C:\Users\ACER\Documents\USU\Semester6\DBS_Journey\membangun_model_msml\.venv\Lib\site-packages\mlflow\utils\rest_utils.py", line 189, in http_request
    return _get_http_response_with_retries(
        method,
    ...<10 lines>...
        **kwargs,
    )
  File "C:\Users\ACER\Documents\USU\Semester6\DBS_Journey\membangun_model_msml\.venv\Lib\site-packages\mlflow\utils\request_utils.py", line 237, in _get_http_response_with_retries
    return session.request(method, url, allow_redirects=allow_redirects, **kwargs)
           ~~~~~~~~~~~~~~~^^^^^^^^^^^^^^^^^^^^^^^^^^^^^^^^^^^^^^^^^^^^^^^^^^^^^^^^
  File "C:\Users\ACER\Documents\USU\Semester6\DBS_Journey\membangun_model_msml\.venv\Lib\site-packages\requests\sessions.py", line 589, in request
    resp = self.send(prep, **send_kwargs)
  File "C:\Users\ACER\Documents\USU\Semester6\DBS_Journey\membangun_model_msml\.venv\Lib\site-packages\requests\sessions.py", line 703, in send
    r = adapter.send(request, **kwargs)
  File "C:\Users\ACER\Documents\USU\Semester6\DBS_Journey\membangun_model_msml\.venv\Lib\site-packages\requests\adapters.py", line 691, in send
    raise RetryError(e, request=request)
requests.exceptions.RetryError: HTTPSConnectionPool(host='dagshub.com', port=443): Max retries exceeded with url: /Rafaellsimarmata/workflow-CI-Rafael-Simarmata.mlflow/api/2.0/mlflow/runs/get?run_uuid=685010e5c60e422c8d1d111c9f2d76a1&run_id=685010e5c60e422c8d1d111c9f2d76a1 (Caused by ResponseError('too many 500 error responses'))

During handling of the above exception, another exception occurred:

Traceback (most recent call last):
  File "C:\Users\ACER\Documents\USU\Semester6\DBS_Journey\membangun_model_msml\MLProject\modelling.py", line 227, in main
    run_id, metrics, cv_accuracy = model_train(
                                   ~~~~~~~~~~~^
        X_train, X_test, y_train, y_test, model_name, params
        ^^^^^^^^^^^^^^^^^^^^^^^^^^^^^^^^^^^^^^^^^^^^^^^^^^^^
    )
    ^
  File "C:\Users\ACER\Documents\USU\Semester6\DBS_Journey\membangun_model_msml\MLProject\modelling.py", line 96, in model_train
    with mlflow.start_run(run_name=f'{model_name}_run_ci') as run:
         ~~~~~~~~~~~~~~~~^^^^^^^^^^^^^^^^^^^^^^^^^^^^^^^^^
  File "C:\Users\ACER\Documents\USU\Semester6\DBS_Journey\membangun_model_msml\.venv\Lib\site-packages\mlflow\tracking\fluent.py", line 368, in start_run
    active_run_obj = client.get_run(existing_run_id)
  File "C:\Users\ACER\Documents\USU\Semester6\DBS_Journey\membangun_model_msml\.venv\Lib\site-packages\mlflow\tracking\client.py", line 226, in get_run
    return self._tracking_client.get_run(run_id)
           ~~~~~~~~~~~~~~~~~~~~~~~~~~~~~^^^^^^^^
  File "C:\Users\ACER\Documents\USU\Semester6\DBS_Journey\membangun_model_msml\.venv\Lib\site-packages\mlflow\tracking\_tracking_service\client.py", line 106, in get_run
    return self.store.get_run(run_id)
           ~~~~~~~~~~~~~~~~~~^^^^^^^^
  File "C:\Users\ACER\Documents\USU\Semester6\DBS_Journey\membangun_model_msml\.venv\Lib\site-packages\mlflow\store\tracking\rest_store.py", line 169, in get_run
    response_proto = self._call_endpoint(GetRun, req_body)
  File "C:\Users\ACER\Documents\USU\Semester6\DBS_Journey\membangun_model_msml\.venv\Lib\site-packages\mlflow\store\tracking\rest_store.py", line 82, in _call_endpoint
    return call_endpoint(self.get_host_creds(), endpoint, method, json_body, response_proto)
  File "C:\Users\ACER\Documents\USU\Semester6\DBS_Journey\membangun_model_msml\.venv\Lib\site-packages\mlflow\utils\rest_utils.py", line 365, in call_endpoint
    response = http_request(**call_kwargs)
  File "C:\Users\ACER\Documents\USU\Semester6\DBS_Journey\membangun_model_msml\.venv\Lib\site-packages\mlflow\utils\rest_utils.py", line 212, in http_request
    raise MlflowException(f"API request to {url} failed with exception {e}")
mlflow.exceptions.MlflowException: API request to https://dagshub.com/Rafaellsimarmata/workflow-CI-Rafael-Simarmata.mlflow/api/2.0/mlflow/runs/get failed with exception HTTPSConnectionPool(host='dagshub.com', port=443): Max retries exceeded with url: /Rafaellsimarmata/workflow-CI-Rafael-Simarmata.mlflow/api/2.0/mlflow/runs/get?run_uuid=685010e5c60e422c8d1d111c9f2d76a1&run_id=685010e5c60e422c8d1d111c9f2d76a1 (Caused by ResponseError('too many 500 error responses'))
2025-07-26 16:35:58 modelling.py [INFO] Loaded .env file from: True
2025-07-26 16:35:58 modelling.py [INFO] Setting tracking URI to: http://localhost:5000
2025-07-26 16:35:58 modelling.py [INFO] MLflow setup completed
2025-07-26 16:35:58 modelling.py [INFO] Loading data from: fraud_detection_processed.csv
2025-07-26 16:35:58 modelling.py [INFO] Data loaded and split. Train: (1212, 9), Test: (304, 9)
2025-07-26 16:35:58 modelling.py [ERROR] An error occurred when training model: API request to endpoint /api/2.0/mlflow/runs/get failed with error code 404 != 200. Response body: ''
Traceback (most recent call last):
  File "C:\Users\ACER\Documents\USU\Semester6\DBS_Journey\membangun_model_msml\MLProject\modelling.py", line 227, in main
    run_id, metrics, cv_accuracy = model_train(
                                   ~~~~~~~~~~~^
        X_train, X_test, y_train, y_test, model_name, params
        ^^^^^^^^^^^^^^^^^^^^^^^^^^^^^^^^^^^^^^^^^^^^^^^^^^^^
    )
    ^
  File "C:\Users\ACER\Documents\USU\Semester6\DBS_Journey\membangun_model_msml\MLProject\modelling.py", line 96, in model_train
    with mlflow.start_run(run_name=f'{model_name}_run_ci') as run:
         ~~~~~~~~~~~~~~~~^^^^^^^^^^^^^^^^^^^^^^^^^^^^^^^^^
  File "C:\Users\ACER\Documents\USU\Semester6\DBS_Journey\membangun_model_msml\.venv\Lib\site-packages\mlflow\tracking\fluent.py", line 368, in start_run
    active_run_obj = client.get_run(existing_run_id)
  File "C:\Users\ACER\Documents\USU\Semester6\DBS_Journey\membangun_model_msml\.venv\Lib\site-packages\mlflow\tracking\client.py", line 226, in get_run
    return self._tracking_client.get_run(run_id)
           ~~~~~~~~~~~~~~~~~~~~~~~~~~~~~^^^^^^^^
  File "C:\Users\ACER\Documents\USU\Semester6\DBS_Journey\membangun_model_msml\.venv\Lib\site-packages\mlflow\tracking\_tracking_service\client.py", line 106, in get_run
    return self.store.get_run(run_id)
           ~~~~~~~~~~~~~~~~~~^^^^^^^^
  File "C:\Users\ACER\Documents\USU\Semester6\DBS_Journey\membangun_model_msml\.venv\Lib\site-packages\mlflow\store\tracking\rest_store.py", line 169, in get_run
    response_proto = self._call_endpoint(GetRun, req_body)
  File "C:\Users\ACER\Documents\USU\Semester6\DBS_Journey\membangun_model_msml\.venv\Lib\site-packages\mlflow\store\tracking\rest_store.py", line 82, in _call_endpoint
    return call_endpoint(self.get_host_creds(), endpoint, method, json_body, response_proto)
  File "C:\Users\ACER\Documents\USU\Semester6\DBS_Journey\membangun_model_msml\.venv\Lib\site-packages\mlflow\utils\rest_utils.py", line 370, in call_endpoint
    response = verify_rest_response(response, endpoint)
  File "C:\Users\ACER\Documents\USU\Semester6\DBS_Journey\membangun_model_msml\.venv\Lib\site-packages\mlflow\utils\rest_utils.py", line 246, in verify_rest_response
    raise MlflowException(
    ...<2 lines>...
    )
mlflow.exceptions.MlflowException: API request to endpoint /api/2.0/mlflow/runs/get failed with error code 404 != 200. Response body: ''
2025-07-26 17:00:33 modelling.py [INFO] Loaded .env file from: True
2025-07-26 17:00:33 modelling.py [INFO] Setting tracking URI to: https://dagshub.com/Rafaellsimarmata/workflow-CI-Rafael-Simarmata.mlflow
2025-07-26 17:00:33 modelling.py [INFO] MLflow setup completed
2025-07-26 17:00:33 modelling.py [INFO] Loading data from: fraud_detection_processed.csv
2025-07-26 17:00:33 modelling.py [INFO] Data loaded and split. Train: (1212, 9), Test: (304, 9)
2025-07-26 17:01:37 modelling.py [ERROR] An error occurred when training model: API request to https://dagshub.com/Rafaellsimarmata/workflow-CI-Rafael-Simarmata.mlflow/api/2.0/mlflow/runs/get failed with exception HTTPSConnectionPool(host='dagshub.com', port=443): Max retries exceeded with url: /Rafaellsimarmata/workflow-CI-Rafael-Simarmata.mlflow/api/2.0/mlflow/runs/get?run_uuid=dd90c54193d64a09b8daabcfd7de7b4b&run_id=dd90c54193d64a09b8daabcfd7de7b4b (Caused by ResponseError('too many 500 error responses'))
urllib3.exceptions.ResponseError: too many 500 error responses

The above exception was the direct cause of the following exception:

Traceback (most recent call last):
  File "C:\Users\ACER\Documents\USU\Semester6\DBS_Journey\membangun_model_msml\.venv\Lib\site-packages\requests\adapters.py", line 667, in send
    resp = conn.urlopen(
        method=request.method,
    ...<9 lines>...
        chunked=chunked,
    )
  File "C:\Users\ACER\Documents\USU\Semester6\DBS_Journey\membangun_model_msml\.venv\Lib\site-packages\urllib3\connectionpool.py", line 942, in urlopen
    return self.urlopen(
           ~~~~~~~~~~~~^
        method,
        ^^^^^^^
    ...<13 lines>...
        **response_kw,
        ^^^^^^^^^^^^^^
    )
    ^
  File "C:\Users\ACER\Documents\USU\Semester6\DBS_Journey\membangun_model_msml\.venv\Lib\site-packages\urllib3\connectionpool.py", line 942, in urlopen
    return self.urlopen(
           ~~~~~~~~~~~~^
        method,
        ^^^^^^^
    ...<13 lines>...
        **response_kw,
        ^^^^^^^^^^^^^^
    )
    ^
  File "C:\Users\ACER\Documents\USU\Semester6\DBS_Journey\membangun_model_msml\.venv\Lib\site-packages\urllib3\connectionpool.py", line 942, in urlopen
    return self.urlopen(
           ~~~~~~~~~~~~^
        method,
        ^^^^^^^
    ...<13 lines>...
        **response_kw,
        ^^^^^^^^^^^^^^
    )
    ^
  [Previous line repeated 2 more times]
  File "C:\Users\ACER\Documents\USU\Semester6\DBS_Journey\membangun_model_msml\.venv\Lib\site-packages\urllib3\connectionpool.py", line 932, in urlopen
    retries = retries.increment(method, url, response=response, _pool=self)
  File "C:\Users\ACER\Documents\USU\Semester6\DBS_Journey\membangun_model_msml\.venv\Lib\site-packages\urllib3\util\retry.py", line 519, in increment
    raise MaxRetryError(_pool, url, reason) from reason  # type: ignore[arg-type]
    ^^^^^^^^^^^^^^^^^^^^^^^^^^^^^^^^^^^^^^^^^^^^^^^^^^^
urllib3.exceptions.MaxRetryError: HTTPSConnectionPool(host='dagshub.com', port=443): Max retries exceeded with url: /Rafaellsimarmata/workflow-CI-Rafael-Simarmata.mlflow/api/2.0/mlflow/runs/get?run_uuid=dd90c54193d64a09b8daabcfd7de7b4b&run_id=dd90c54193d64a09b8daabcfd7de7b4b (Caused by ResponseError('too many 500 error responses'))

During handling of the above exception, another exception occurred:

Traceback (most recent call last):
  File "C:\Users\ACER\Documents\USU\Semester6\DBS_Journey\membangun_model_msml\.venv\Lib\site-packages\mlflow\utils\rest_utils.py", line 189, in http_request
    return _get_http_response_with_retries(
        method,
    ...<10 lines>...
        **kwargs,
    )
  File "C:\Users\ACER\Documents\USU\Semester6\DBS_Journey\membangun_model_msml\.venv\Lib\site-packages\mlflow\utils\request_utils.py", line 237, in _get_http_response_with_retries
    return session.request(method, url, allow_redirects=allow_redirects, **kwargs)
           ~~~~~~~~~~~~~~~^^^^^^^^^^^^^^^^^^^^^^^^^^^^^^^^^^^^^^^^^^^^^^^^^^^^^^^^
  File "C:\Users\ACER\Documents\USU\Semester6\DBS_Journey\membangun_model_msml\.venv\Lib\site-packages\requests\sessions.py", line 589, in request
    resp = self.send(prep, **send_kwargs)
  File "C:\Users\ACER\Documents\USU\Semester6\DBS_Journey\membangun_model_msml\.venv\Lib\site-packages\requests\sessions.py", line 703, in send
    r = adapter.send(request, **kwargs)
  File "C:\Users\ACER\Documents\USU\Semester6\DBS_Journey\membangun_model_msml\.venv\Lib\site-packages\requests\adapters.py", line 691, in send
    raise RetryError(e, request=request)
requests.exceptions.RetryError: HTTPSConnectionPool(host='dagshub.com', port=443): Max retries exceeded with url: /Rafaellsimarmata/workflow-CI-Rafael-Simarmata.mlflow/api/2.0/mlflow/runs/get?run_uuid=dd90c54193d64a09b8daabcfd7de7b4b&run_id=dd90c54193d64a09b8daabcfd7de7b4b (Caused by ResponseError('too many 500 error responses'))

During handling of the above exception, another exception occurred:

Traceback (most recent call last):
  File "C:\Users\ACER\Documents\USU\Semester6\DBS_Journey\membangun_model_msml\MLProject\modelling.py", line 227, in main
    run_id, metrics, cv_accuracy = model_train(
                                   ~~~~~~~~~~~^
        X_train, X_test, y_train, y_test, model_name, params
        ^^^^^^^^^^^^^^^^^^^^^^^^^^^^^^^^^^^^^^^^^^^^^^^^^^^^
    )
    ^
  File "C:\Users\ACER\Documents\USU\Semester6\DBS_Journey\membangun_model_msml\MLProject\modelling.py", line 96, in model_train
    with mlflow.start_run(run_name=f'{model_name}_run_ci') as run:
         ~~~~~~~~~~~~~~~~^^^^^^^^^^^^^^^^^^^^^^^^^^^^^^^^^
  File "C:\Users\ACER\Documents\USU\Semester6\DBS_Journey\membangun_model_msml\.venv\Lib\site-packages\mlflow\tracking\fluent.py", line 368, in start_run
    active_run_obj = client.get_run(existing_run_id)
  File "C:\Users\ACER\Documents\USU\Semester6\DBS_Journey\membangun_model_msml\.venv\Lib\site-packages\mlflow\tracking\client.py", line 226, in get_run
    return self._tracking_client.get_run(run_id)
           ~~~~~~~~~~~~~~~~~~~~~~~~~~~~~^^^^^^^^
  File "C:\Users\ACER\Documents\USU\Semester6\DBS_Journey\membangun_model_msml\.venv\Lib\site-packages\mlflow\tracking\_tracking_service\client.py", line 106, in get_run
    return self.store.get_run(run_id)
           ~~~~~~~~~~~~~~~~~~^^^^^^^^
  File "C:\Users\ACER\Documents\USU\Semester6\DBS_Journey\membangun_model_msml\.venv\Lib\site-packages\mlflow\store\tracking\rest_store.py", line 169, in get_run
    response_proto = self._call_endpoint(GetRun, req_body)
  File "C:\Users\ACER\Documents\USU\Semester6\DBS_Journey\membangun_model_msml\.venv\Lib\site-packages\mlflow\store\tracking\rest_store.py", line 82, in _call_endpoint
    return call_endpoint(self.get_host_creds(), endpoint, method, json_body, response_proto)
  File "C:\Users\ACER\Documents\USU\Semester6\DBS_Journey\membangun_model_msml\.venv\Lib\site-packages\mlflow\utils\rest_utils.py", line 365, in call_endpoint
    response = http_request(**call_kwargs)
  File "C:\Users\ACER\Documents\USU\Semester6\DBS_Journey\membangun_model_msml\.venv\Lib\site-packages\mlflow\utils\rest_utils.py", line 212, in http_request
    raise MlflowException(f"API request to {url} failed with exception {e}")
mlflow.exceptions.MlflowException: API request to https://dagshub.com/Rafaellsimarmata/workflow-CI-Rafael-Simarmata.mlflow/api/2.0/mlflow/runs/get failed with exception HTTPSConnectionPool(host='dagshub.com', port=443): Max retries exceeded with url: /Rafaellsimarmata/workflow-CI-Rafael-Simarmata.mlflow/api/2.0/mlflow/runs/get?run_uuid=dd90c54193d64a09b8daabcfd7de7b4b&run_id=dd90c54193d64a09b8daabcfd7de7b4b (Caused by ResponseError('too many 500 error responses'))
2025-07-26 18:07:22 modelling.py [INFO] Loaded .env file from: True
2025-07-26 18:07:23 modelling.py [INFO] Setting tracking URI to: https://dagshub.com/Rafaellsimarmata/workflow-CI-Rafael-Simarmata.mlflow
2025-07-26 18:07:23 modelling.py [INFO] MLflow setup completed
2025-07-26 18:07:23 modelling.py [INFO] Loading data from: fraud_detection_processed.csv
2025-07-26 18:07:23 modelling.py [INFO] Data loaded and split. Train: (1212, 9), Test: (304, 9)
2025-07-26 18:11:33 modelling.py [ERROR] An error occurred when training model: API request to https://dagshub.com/Rafaellsimarmata/workflow-CI-Rafael-Simarmata.mlflow/api/2.0/mlflow/runs/get failed with exception HTTPSConnectionPool(host='dagshub.com', port=443): Max retries exceeded with url: /Rafaellsimarmata/workflow-CI-Rafael-Simarmata.mlflow/api/2.0/mlflow/runs/get?run_uuid=1339c5b12a6744218087d38d37c6967e&run_id=1339c5b12a6744218087d38d37c6967e (Caused by ResponseError('too many 500 error responses'))
urllib3.exceptions.ResponseError: too many 500 error responses

The above exception was the direct cause of the following exception:

Traceback (most recent call last):
  File "C:\Users\ACER\Documents\USU\Semester6\DBS_Journey\membangun_model_msml\.venv\Lib\site-packages\requests\adapters.py", line 667, in send
    resp = conn.urlopen(
        method=request.method,
    ...<9 lines>...
        chunked=chunked,
    )
  File "C:\Users\ACER\Documents\USU\Semester6\DBS_Journey\membangun_model_msml\.venv\Lib\site-packages\urllib3\connectionpool.py", line 942, in urlopen
    return self.urlopen(
           ~~~~~~~~~~~~^
        method,
        ^^^^^^^
    ...<13 lines>...
        **response_kw,
        ^^^^^^^^^^^^^^
    )
    ^
  File "C:\Users\ACER\Documents\USU\Semester6\DBS_Journey\membangun_model_msml\.venv\Lib\site-packages\urllib3\connectionpool.py", line 942, in urlopen
    return self.urlopen(
           ~~~~~~~~~~~~^
        method,
        ^^^^^^^
    ...<13 lines>...
        **response_kw,
        ^^^^^^^^^^^^^^
    )
    ^
  File "C:\Users\ACER\Documents\USU\Semester6\DBS_Journey\membangun_model_msml\.venv\Lib\site-packages\urllib3\connectionpool.py", line 942, in urlopen
    return self.urlopen(
           ~~~~~~~~~~~~^
        method,
        ^^^^^^^
    ...<13 lines>...
        **response_kw,
        ^^^^^^^^^^^^^^
    )
    ^
  [Previous line repeated 4 more times]
  File "C:\Users\ACER\Documents\USU\Semester6\DBS_Journey\membangun_model_msml\.venv\Lib\site-packages\urllib3\connectionpool.py", line 932, in urlopen
    retries = retries.increment(method, url, response=response, _pool=self)
  File "C:\Users\ACER\Documents\USU\Semester6\DBS_Journey\membangun_model_msml\.venv\Lib\site-packages\urllib3\util\retry.py", line 519, in increment
    raise MaxRetryError(_pool, url, reason) from reason  # type: ignore[arg-type]
    ^^^^^^^^^^^^^^^^^^^^^^^^^^^^^^^^^^^^^^^^^^^^^^^^^^^
urllib3.exceptions.MaxRetryError: HTTPSConnectionPool(host='dagshub.com', port=443): Max retries exceeded with url: /Rafaellsimarmata/workflow-CI-Rafael-Simarmata.mlflow/api/2.0/mlflow/runs/get?run_uuid=1339c5b12a6744218087d38d37c6967e&run_id=1339c5b12a6744218087d38d37c6967e (Caused by ResponseError('too many 500 error responses'))

During handling of the above exception, another exception occurred:

Traceback (most recent call last):
  File "C:\Users\ACER\Documents\USU\Semester6\DBS_Journey\membangun_model_msml\.venv\Lib\site-packages\mlflow\utils\rest_utils.py", line 230, in http_request
    return _get_http_response_with_retries(
        method,
    ...<10 lines>...
        **kwargs,
    )
  File "C:\Users\ACER\Documents\USU\Semester6\DBS_Journey\membangun_model_msml\.venv\Lib\site-packages\mlflow\utils\request_utils.py", line 237, in _get_http_response_with_retries
    return session.request(method, url, allow_redirects=allow_redirects, **kwargs)
           ~~~~~~~~~~~~~~~^^^^^^^^^^^^^^^^^^^^^^^^^^^^^^^^^^^^^^^^^^^^^^^^^^^^^^^^
  File "C:\Users\ACER\Documents\USU\Semester6\DBS_Journey\membangun_model_msml\.venv\Lib\site-packages\requests\sessions.py", line 589, in request
    resp = self.send(prep, **send_kwargs)
  File "C:\Users\ACER\Documents\USU\Semester6\DBS_Journey\membangun_model_msml\.venv\Lib\site-packages\requests\sessions.py", line 703, in send
    r = adapter.send(request, **kwargs)
  File "C:\Users\ACER\Documents\USU\Semester6\DBS_Journey\membangun_model_msml\.venv\Lib\site-packages\requests\adapters.py", line 691, in send
    raise RetryError(e, request=request)
requests.exceptions.RetryError: HTTPSConnectionPool(host='dagshub.com', port=443): Max retries exceeded with url: /Rafaellsimarmata/workflow-CI-Rafael-Simarmata.mlflow/api/2.0/mlflow/runs/get?run_uuid=1339c5b12a6744218087d38d37c6967e&run_id=1339c5b12a6744218087d38d37c6967e (Caused by ResponseError('too many 500 error responses'))

During handling of the above exception, another exception occurred:

Traceback (most recent call last):
  File "C:\Users\ACER\Documents\USU\Semester6\DBS_Journey\membangun_model_msml\MLProject\modelling.py", line 227, in main
    run_id, metrics, cv_accuracy = model_train(
                                   ~~~~~~~~~~~^
        X_train, X_test, y_train, y_test, model_name, params
        ^^^^^^^^^^^^^^^^^^^^^^^^^^^^^^^^^^^^^^^^^^^^^^^^^^^^
    )
    ^
  File "C:\Users\ACER\Documents\USU\Semester6\DBS_Journey\membangun_model_msml\MLProject\modelling.py", line 96, in model_train
    with mlflow.start_run(run_name=f'{model_name}_run_ci') as run:
         ~~~~~~~~~~~~~~~~^^^^^^^^^^^^^^^^^^^^^^^^^^^^^^^^^
  File "C:\Users\ACER\Documents\USU\Semester6\DBS_Journey\membangun_model_msml\.venv\Lib\site-packages\mlflow\tracking\fluent.py", line 396, in start_run
    active_run_obj = client.get_run(existing_run_id)
  File "C:\Users\ACER\Documents\USU\Semester6\DBS_Journey\membangun_model_msml\.venv\Lib\site-packages\mlflow\tracking\client.py", line 268, in get_run
    return self._tracking_client.get_run(run_id)
           ~~~~~~~~~~~~~~~~~~~~~~~~~~~~~^^^^^^^^
  File "C:\Users\ACER\Documents\USU\Semester6\DBS_Journey\membangun_model_msml\.venv\Lib\site-packages\mlflow\tracking\_tracking_service\client.py", line 98, in get_run
    return self.store.get_run(run_id)
           ~~~~~~~~~~~~~~~~~~^^^^^^^^
  File "C:\Users\ACER\Documents\USU\Semester6\DBS_Journey\membangun_model_msml\.venv\Lib\site-packages\mlflow\store\tracking\rest_store.py", line 229, in get_run
    response_proto = self._call_endpoint(GetRun, req_body)
  File "C:\Users\ACER\Documents\USU\Semester6\DBS_Journey\membangun_model_msml\.venv\Lib\site-packages\mlflow\store\tracking\rest_store.py", line 135, in _call_endpoint
    return call_endpoint(
        self.get_host_creds(),
    ...<4 lines>...
        retry_timeout_seconds=retry_timeout_seconds,
    )
  File "C:\Users\ACER\Documents\USU\Semester6\DBS_Journey\membangun_model_msml\.venv\Lib\site-packages\mlflow\utils\rest_utils.py", line 589, in call_endpoint
    response = http_request(**call_kwargs)
  File "C:\Users\ACER\Documents\USU\Semester6\DBS_Journey\membangun_model_msml\.venv\Lib\site-packages\mlflow\utils\rest_utils.py", line 253, in http_request
    raise MlflowException(f"API request to {url} failed with exception {e}")
mlflow.exceptions.MlflowException: API request to https://dagshub.com/Rafaellsimarmata/workflow-CI-Rafael-Simarmata.mlflow/api/2.0/mlflow/runs/get failed with exception HTTPSConnectionPool(host='dagshub.com', port=443): Max retries exceeded with url: /Rafaellsimarmata/workflow-CI-Rafael-Simarmata.mlflow/api/2.0/mlflow/runs/get?run_uuid=1339c5b12a6744218087d38d37c6967e&run_id=1339c5b12a6744218087d38d37c6967e (Caused by ResponseError('too many 500 error responses'))
2025-07-26 20:12:05 modelling.py [INFO] Loaded .env file from: True
2025-07-26 20:12:05 modelling.py [INFO] Setting tracking URI to: https://dagshub.com/Rafaellsimarmata/workflow-CI-Rafael-Simarmata.mlflow
2025-07-26 20:12:05 modelling.py [INFO] MLflow setup completed
2025-07-26 20:12:05 modelling.py [INFO] Loading data from: fraud_detection_processed.csv
2025-07-26 20:12:05 modelling.py [INFO] Data loaded and split. Train: (1212, 9), Test: (304, 9)
2025-07-26 20:13:11 modelling.py [ERROR] An error occurred when training model: API request to https://dagshub.com/Rafaellsimarmata/workflow-CI-Rafael-Simarmata.mlflow/api/2.0/mlflow/runs/get failed with exception HTTPSConnectionPool(host='dagshub.com', port=443): Max retries exceeded with url: /Rafaellsimarmata/workflow-CI-Rafael-Simarmata.mlflow/api/2.0/mlflow/runs/get?run_uuid=eb78c4550b76465cafc2fbd8ebd237b8&run_id=eb78c4550b76465cafc2fbd8ebd237b8 (Caused by ResponseError('too many 500 error responses'))
urllib3.exceptions.ResponseError: too many 500 error responses

The above exception was the direct cause of the following exception:

Traceback (most recent call last):
  File "C:\Users\ACER\Documents\USU\Semester6\DBS_Journey\membangun_model_msml\.venv\Lib\site-packages\requests\adapters.py", line 667, in send
    resp = conn.urlopen(
           ^^^^^^^^^^^^^
  File "C:\Users\ACER\Documents\USU\Semester6\DBS_Journey\membangun_model_msml\.venv\Lib\site-packages\urllib3\connectionpool.py", line 942, in urlopen
    return self.urlopen(
           ^^^^^^^^^^^^^
  File "C:\Users\ACER\Documents\USU\Semester6\DBS_Journey\membangun_model_msml\.venv\Lib\site-packages\urllib3\connectionpool.py", line 942, in urlopen
    return self.urlopen(
           ^^^^^^^^^^^^^
  File "C:\Users\ACER\Documents\USU\Semester6\DBS_Journey\membangun_model_msml\.venv\Lib\site-packages\urllib3\connectionpool.py", line 942, in urlopen
    return self.urlopen(
           ^^^^^^^^^^^^^
  [Previous line repeated 2 more times]
  File "C:\Users\ACER\Documents\USU\Semester6\DBS_Journey\membangun_model_msml\.venv\Lib\site-packages\urllib3\connectionpool.py", line 932, in urlopen
    retries = retries.increment(method, url, response=response, _pool=self)
              ^^^^^^^^^^^^^^^^^^^^^^^^^^^^^^^^^^^^^^^^^^^^^^^^^^^^^^^^^^^^^
  File "C:\Users\ACER\Documents\USU\Semester6\DBS_Journey\membangun_model_msml\.venv\Lib\site-packages\urllib3\util\retry.py", line 519, in increment
    raise MaxRetryError(_pool, url, reason) from reason  # type: ignore[arg-type]
    ^^^^^^^^^^^^^^^^^^^^^^^^^^^^^^^^^^^^^^^^^^^^^^^^^^^
urllib3.exceptions.MaxRetryError: HTTPSConnectionPool(host='dagshub.com', port=443): Max retries exceeded with url: /Rafaellsimarmata/workflow-CI-Rafael-Simarmata.mlflow/api/2.0/mlflow/runs/get?run_uuid=eb78c4550b76465cafc2fbd8ebd237b8&run_id=eb78c4550b76465cafc2fbd8ebd237b8 (Caused by ResponseError('too many 500 error responses'))

During handling of the above exception, another exception occurred:

Traceback (most recent call last):
  File "C:\Users\ACER\Documents\USU\Semester6\DBS_Journey\membangun_model_msml\.venv\Lib\site-packages\mlflow\utils\rest_utils.py", line 189, in http_request
    return _get_http_response_with_retries(
           ^^^^^^^^^^^^^^^^^^^^^^^^^^^^^^^^
  File "C:\Users\ACER\Documents\USU\Semester6\DBS_Journey\membangun_model_msml\.venv\Lib\site-packages\mlflow\utils\request_utils.py", line 237, in _get_http_response_with_retries
    return session.request(method, url, allow_redirects=allow_redirects, **kwargs)
           ^^^^^^^^^^^^^^^^^^^^^^^^^^^^^^^^^^^^^^^^^^^^^^^^^^^^^^^^^^^^^^^^^^^^^^^
  File "C:\Users\ACER\Documents\USU\Semester6\DBS_Journey\membangun_model_msml\.venv\Lib\site-packages\requests\sessions.py", line 589, in request
    resp = self.send(prep, **send_kwargs)
           ^^^^^^^^^^^^^^^^^^^^^^^^^^^^^^
  File "C:\Users\ACER\Documents\USU\Semester6\DBS_Journey\membangun_model_msml\.venv\Lib\site-packages\requests\sessions.py", line 703, in send
    r = adapter.send(request, **kwargs)
        ^^^^^^^^^^^^^^^^^^^^^^^^^^^^^^^
  File "C:\Users\ACER\Documents\USU\Semester6\DBS_Journey\membangun_model_msml\.venv\Lib\site-packages\requests\adapters.py", line 691, in send
    raise RetryError(e, request=request)
requests.exceptions.RetryError: HTTPSConnectionPool(host='dagshub.com', port=443): Max retries exceeded with url: /Rafaellsimarmata/workflow-CI-Rafael-Simarmata.mlflow/api/2.0/mlflow/runs/get?run_uuid=eb78c4550b76465cafc2fbd8ebd237b8&run_id=eb78c4550b76465cafc2fbd8ebd237b8 (Caused by ResponseError('too many 500 error responses'))

During handling of the above exception, another exception occurred:

Traceback (most recent call last):
  File "C:\Users\ACER\Documents\USU\Semester6\DBS_Journey\membangun_model_msml\MLProject\modelling.py", line 227, in main
    run_id, metrics, cv_accuracy = model_train(
                                   ^^^^^^^^^^^^
  File "C:\Users\ACER\Documents\USU\Semester6\DBS_Journey\membangun_model_msml\MLProject\modelling.py", line 96, in model_train
    with mlflow.start_run(run_name=f'{model_name}_run_ci') as run:
         ^^^^^^^^^^^^^^^^^^^^^^^^^^^^^^^^^^^^^^^^^^^^^^^^^
  File "C:\Users\ACER\Documents\USU\Semester6\DBS_Journey\membangun_model_msml\.venv\Lib\site-packages\mlflow\tracking\fluent.py", line 368, in start_run
    active_run_obj = client.get_run(existing_run_id)
                     ^^^^^^^^^^^^^^^^^^^^^^^^^^^^^^^
  File "C:\Users\ACER\Documents\USU\Semester6\DBS_Journey\membangun_model_msml\.venv\Lib\site-packages\mlflow\tracking\client.py", line 226, in get_run
    return self._tracking_client.get_run(run_id)
           ^^^^^^^^^^^^^^^^^^^^^^^^^^^^^^^^^^^^^
  File "C:\Users\ACER\Documents\USU\Semester6\DBS_Journey\membangun_model_msml\.venv\Lib\site-packages\mlflow\tracking\_tracking_service\client.py", line 106, in get_run
    return self.store.get_run(run_id)
           ^^^^^^^^^^^^^^^^^^^^^^^^^^
  File "C:\Users\ACER\Documents\USU\Semester6\DBS_Journey\membangun_model_msml\.venv\Lib\site-packages\mlflow\store\tracking\rest_store.py", line 169, in get_run
    response_proto = self._call_endpoint(GetRun, req_body)
                     ^^^^^^^^^^^^^^^^^^^^^^^^^^^^^^^^^^^^^
  File "C:\Users\ACER\Documents\USU\Semester6\DBS_Journey\membangun_model_msml\.venv\Lib\site-packages\mlflow\store\tracking\rest_store.py", line 82, in _call_endpoint
    return call_endpoint(self.get_host_creds(), endpoint, method, json_body, response_proto)
           ^^^^^^^^^^^^^^^^^^^^^^^^^^^^^^^^^^^^^^^^^^^^^^^^^^^^^^^^^^^^^^^^^^^^^^^^^^^^^^^^^
  File "C:\Users\ACER\Documents\USU\Semester6\DBS_Journey\membangun_model_msml\.venv\Lib\site-packages\mlflow\utils\rest_utils.py", line 365, in call_endpoint
    response = http_request(**call_kwargs)
               ^^^^^^^^^^^^^^^^^^^^^^^^^^^
  File "C:\Users\ACER\Documents\USU\Semester6\DBS_Journey\membangun_model_msml\.venv\Lib\site-packages\mlflow\utils\rest_utils.py", line 212, in http_request
    raise MlflowException(f"API request to {url} failed with exception {e}")
mlflow.exceptions.MlflowException: API request to https://dagshub.com/Rafaellsimarmata/workflow-CI-Rafael-Simarmata.mlflow/api/2.0/mlflow/runs/get failed with exception HTTPSConnectionPool(host='dagshub.com', port=443): Max retries exceeded with url: /Rafaellsimarmata/workflow-CI-Rafael-Simarmata.mlflow/api/2.0/mlflow/runs/get?run_uuid=eb78c4550b76465cafc2fbd8ebd237b8&run_id=eb78c4550b76465cafc2fbd8ebd237b8 (Caused by ResponseError('too many 500 error responses'))
2025-07-26 21:03:17 modelling.py [INFO] Loaded .env file from: True
2025-07-26 21:03:17 modelling.py [ERROR] MLflow setup failed: 'MlflowClient' object has no attribute 'list_experiments'
Traceback (most recent call last):
  File "C:\Users\ACER\Documents\USU\Semester6\DBS_Journey\membangun_model_msml\MLProject\modelling.py", line 53, in mlflow_setup
    client.list_experiments()  # Test API call
    ^^^^^^^^^^^^^^^^^^^^^^^
AttributeError: 'MlflowClient' object has no attribute 'list_experiments'. Did you mean: 'get_experiment'?
2025-07-26 21:03:17 modelling.py [INFO] Falling back to local MLflow tracking
2025-07-26 21:03:17 modelling.py [INFO] Loading data from: fraud_detection_processed.csv
2025-07-26 21:03:17 modelling.py [INFO] Data loaded and split. Train: (1212, 9), Test: (304, 9)
2025-07-26 21:03:18 modelling.py [INFO] Model training started: rf. Parameters: {'n_estimators': 100, 'max_depth': 10}
2025-07-26 21:03:42 modelling.py [INFO] Model training completed.
2025-07-26 21:03:43 modelling.py [INFO] Model RandomForestClassifier(max_depth=10, random_state=42) evaluated. Accuracy: 0.9605.
2025-07-26 21:04:40 modelling.py [INFO] Cross-validation accuracy: 0.9488
2025-07-26 21:04:40 modelling.py [INFO] Metrics logged to MLflow.
2025-07-26 21:04:40 modelling.py [INFO] Confusion matrix logged as CSV and PNG to MLflow.
2025-07-26 21:04:41 modelling.py [INFO] Feature importance logged to MLflow.
2025-07-26 21:04:41 modelling.py [INFO] Metrics saved and logged to MLflow.
2025-07-26 21:04:50 modelling.py [INFO] Model artifact saved and logged to MLflow.
2025-07-26 21:04:51 modelling.py [INFO] Model rf trained and logged successfully.
2025-07-26 21:04:51 modelling.py [INFO] Run ID: ad5b6b7e6fa2427e9602e9a2db3ca636
2025-07-26 21:04:51 modelling.py [INFO] Accuracy: 0.9605
2025-07-26 21:04:51 modelling.py [INFO] Cross-validation accuracy: 0.9488
2025-07-26 21:04:51 modelling.py [INFO] Run ID saved to file.
2025-07-26 21:05:31 modelling.py [INFO] Loaded .env file from: True
2025-07-26 21:05:31 modelling.py [ERROR] MLflow setup failed: MlflowClient.get_experiment() missing 1 required positional argument: 'experiment_id'
Traceback (most recent call last):
  File "C:\Users\ACER\Documents\USU\Semester6\DBS_Journey\membangun_model_msml\MLProject\modelling.py", line 53, in mlflow_setup
    client.get_experiment()  # Test API call
    ~~~~~~~~~~~~~~~~~~~~~^^
TypeError: MlflowClient.get_experiment() missing 1 required positional argument: 'experiment_id'
2025-07-26 21:05:31 modelling.py [INFO] Falling back to local MLflow tracking
2025-07-26 21:05:31 modelling.py [INFO] Loading data from: fraud_detection_processed.csv
2025-07-26 21:05:31 modelling.py [INFO] Data loaded and split. Train: (1212, 9), Test: (304, 9)
2025-07-26 21:05:31 modelling.py [INFO] Model training started: rf. Parameters: {'n_estimators': 100, 'max_depth': 10}
2025-07-26 21:05:48 modelling.py [INFO] Model training completed.
2025-07-26 21:05:48 modelling.py [INFO] Model RandomForestClassifier(max_depth=10, random_state=42) evaluated. Accuracy: 0.9605.
2025-07-26 21:06:22 modelling.py [INFO] Loaded .env file from: True
2025-07-26 21:06:22 modelling.py [INFO] Setting tracking URI to: https://dagshub.com/Rafaellsimarmata/workflow-CI-Rafael-Simarmata.mlflow
2025-07-26 21:06:22 modelling.py [INFO] MLflow setup completed
2025-07-26 21:06:22 modelling.py [INFO] Loading data from: fraud_detection_processed.csv
2025-07-26 21:06:23 modelling.py [INFO] Data loaded and split. Train: (1212, 9), Test: (304, 9)
2025-07-26 21:10:34 modelling.py [ERROR] An error occurred when training model: API request to https://dagshub.com/Rafaellsimarmata/workflow-CI-Rafael-Simarmata.mlflow/api/2.0/mlflow/runs/get failed with exception HTTPSConnectionPool(host='dagshub.com', port=443): Max retries exceeded with url: /Rafaellsimarmata/workflow-CI-Rafael-Simarmata.mlflow/api/2.0/mlflow/runs/get?run_uuid=21ef66147afd4b6daf7a52cc7cbef42d&run_id=21ef66147afd4b6daf7a52cc7cbef42d (Caused by ResponseError('too many 500 error responses'))
urllib3.exceptions.ResponseError: too many 500 error responses

The above exception was the direct cause of the following exception:

Traceback (most recent call last):
  File "C:\Users\ACER\Documents\USU\Semester6\DBS_Journey\membangun_model_msml\.venv\Lib\site-packages\requests\adapters.py", line 667, in send
    resp = conn.urlopen(
        method=request.method,
    ...<9 lines>...
        chunked=chunked,
    )
  File "C:\Users\ACER\Documents\USU\Semester6\DBS_Journey\membangun_model_msml\.venv\Lib\site-packages\urllib3\connectionpool.py", line 942, in urlopen
    return self.urlopen(
           ~~~~~~~~~~~~^
        method,
        ^^^^^^^
    ...<13 lines>...
        **response_kw,
        ^^^^^^^^^^^^^^
    )
    ^
  File "C:\Users\ACER\Documents\USU\Semester6\DBS_Journey\membangun_model_msml\.venv\Lib\site-packages\urllib3\connectionpool.py", line 942, in urlopen
    return self.urlopen(
           ~~~~~~~~~~~~^
        method,
        ^^^^^^^
    ...<13 lines>...
        **response_kw,
        ^^^^^^^^^^^^^^
    )
    ^
  File "C:\Users\ACER\Documents\USU\Semester6\DBS_Journey\membangun_model_msml\.venv\Lib\site-packages\urllib3\connectionpool.py", line 942, in urlopen
    return self.urlopen(
           ~~~~~~~~~~~~^
        method,
        ^^^^^^^
    ...<13 lines>...
        **response_kw,
        ^^^^^^^^^^^^^^
    )
    ^
  [Previous line repeated 4 more times]
  File "C:\Users\ACER\Documents\USU\Semester6\DBS_Journey\membangun_model_msml\.venv\Lib\site-packages\urllib3\connectionpool.py", line 932, in urlopen
    retries = retries.increment(method, url, response=response, _pool=self)
  File "C:\Users\ACER\Documents\USU\Semester6\DBS_Journey\membangun_model_msml\.venv\Lib\site-packages\urllib3\util\retry.py", line 519, in increment
    raise MaxRetryError(_pool, url, reason) from reason  # type: ignore[arg-type]
    ^^^^^^^^^^^^^^^^^^^^^^^^^^^^^^^^^^^^^^^^^^^^^^^^^^^
urllib3.exceptions.MaxRetryError: HTTPSConnectionPool(host='dagshub.com', port=443): Max retries exceeded with url: /Rafaellsimarmata/workflow-CI-Rafael-Simarmata.mlflow/api/2.0/mlflow/runs/get?run_uuid=21ef66147afd4b6daf7a52cc7cbef42d&run_id=21ef66147afd4b6daf7a52cc7cbef42d (Caused by ResponseError('too many 500 error responses'))

During handling of the above exception, another exception occurred:

Traceback (most recent call last):
  File "C:\Users\ACER\Documents\USU\Semester6\DBS_Journey\membangun_model_msml\.venv\Lib\site-packages\mlflow\utils\rest_utils.py", line 184, in http_request
    return _get_http_response_with_retries(
        method,
    ...<10 lines>...
        **kwargs,
    )
  File "C:\Users\ACER\Documents\USU\Semester6\DBS_Journey\membangun_model_msml\.venv\Lib\site-packages\mlflow\utils\request_utils.py", line 237, in _get_http_response_with_retries
    return session.request(method, url, allow_redirects=allow_redirects, **kwargs)
           ~~~~~~~~~~~~~~~^^^^^^^^^^^^^^^^^^^^^^^^^^^^^^^^^^^^^^^^^^^^^^^^^^^^^^^^
  File "C:\Users\ACER\Documents\USU\Semester6\DBS_Journey\membangun_model_msml\.venv\Lib\site-packages\requests\sessions.py", line 589, in request
    resp = self.send(prep, **send_kwargs)
  File "C:\Users\ACER\Documents\USU\Semester6\DBS_Journey\membangun_model_msml\.venv\Lib\site-packages\requests\sessions.py", line 703, in send
    r = adapter.send(request, **kwargs)
  File "C:\Users\ACER\Documents\USU\Semester6\DBS_Journey\membangun_model_msml\.venv\Lib\site-packages\requests\adapters.py", line 691, in send
    raise RetryError(e, request=request)
requests.exceptions.RetryError: HTTPSConnectionPool(host='dagshub.com', port=443): Max retries exceeded with url: /Rafaellsimarmata/workflow-CI-Rafael-Simarmata.mlflow/api/2.0/mlflow/runs/get?run_uuid=21ef66147afd4b6daf7a52cc7cbef42d&run_id=21ef66147afd4b6daf7a52cc7cbef42d (Caused by ResponseError('too many 500 error responses'))

During handling of the above exception, another exception occurred:

Traceback (most recent call last):
  File "C:\Users\ACER\Documents\USU\Semester6\DBS_Journey\membangun_model_msml\MLProject\modelling.py", line 234, in main
    run_id, metrics, cv_accuracy = model_train(
                                   ~~~~~~~~~~~^
        X_train, X_test, y_train, y_test, model_name, params
        ^^^^^^^^^^^^^^^^^^^^^^^^^^^^^^^^^^^^^^^^^^^^^^^^^^^^
    )
    ^
  File "C:\Users\ACER\Documents\USU\Semester6\DBS_Journey\membangun_model_msml\MLProject\modelling.py", line 103, in model_train
    with mlflow.start_run(run_name=f'{model_name}_run_ci') as run:
         ~~~~~~~~~~~~~~~~^^^^^^^^^^^^^^^^^^^^^^^^^^^^^^^^^
  File "C:\Users\ACER\Documents\USU\Semester6\DBS_Journey\membangun_model_msml\.venv\Lib\site-packages\mlflow\tracking\fluent.py", line 368, in start_run
    active_run_obj = client.get_run(existing_run_id)
  File "C:\Users\ACER\Documents\USU\Semester6\DBS_Journey\membangun_model_msml\.venv\Lib\site-packages\mlflow\tracking\client.py", line 251, in get_run
    return self._tracking_client.get_run(run_id)
           ~~~~~~~~~~~~~~~~~~~~~~~~~~~~~^^^^^^^^
  File "C:\Users\ACER\Documents\USU\Semester6\DBS_Journey\membangun_model_msml\.venv\Lib\site-packages\mlflow\tracking\_tracking_service\client.py", line 108, in get_run
    return self.store.get_run(run_id)
           ~~~~~~~~~~~~~~~~~~^^^^^^^^
  File "C:\Users\ACER\Documents\USU\Semester6\DBS_Journey\membangun_model_msml\.venv\Lib\site-packages\mlflow\store\tracking\rest_store.py", line 177, in get_run
    response_proto = self._call_endpoint(GetRun, req_body)
  File "C:\Users\ACER\Documents\USU\Semester6\DBS_Journey\membangun_model_msml\.venv\Lib\site-packages\mlflow\store\tracking\rest_store.py", line 90, in _call_endpoint
    return call_endpoint(self.get_host_creds(), endpoint, method, json_body, response_proto)
  File "C:\Users\ACER\Documents\USU\Semester6\DBS_Journey\membangun_model_msml\.venv\Lib\site-packages\mlflow\utils\rest_utils.py", line 397, in call_endpoint
    response = http_request(**call_kwargs)
  File "C:\Users\ACER\Documents\USU\Semester6\DBS_Journey\membangun_model_msml\.venv\Lib\site-packages\mlflow\utils\rest_utils.py", line 207, in http_request
    raise MlflowException(f"API request to {url} failed with exception {e}")
mlflow.exceptions.MlflowException: API request to https://dagshub.com/Rafaellsimarmata/workflow-CI-Rafael-Simarmata.mlflow/api/2.0/mlflow/runs/get failed with exception HTTPSConnectionPool(host='dagshub.com', port=443): Max retries exceeded with url: /Rafaellsimarmata/workflow-CI-Rafael-Simarmata.mlflow/api/2.0/mlflow/runs/get?run_uuid=21ef66147afd4b6daf7a52cc7cbef42d&run_id=21ef66147afd4b6daf7a52cc7cbef42d (Caused by ResponseError('too many 500 error responses'))
2025-07-26 21:11:14 modelling.py [INFO] Loaded .env file from: True
2025-07-26 21:11:14 modelling.py [INFO] Setting tracking URI to: http://localhost:5000
2025-07-26 21:11:14 modelling.py [INFO] MLflow setup completed
2025-07-26 21:11:14 modelling.py [INFO] Loading data from: fraud_detection_processed.csv
2025-07-26 21:11:14 modelling.py [INFO] Data loaded and split. Train: (1212, 9), Test: (304, 9)
2025-07-26 21:11:17 modelling.py [INFO] Model training started: rf. Parameters: {'n_estimators': 100, 'max_depth': 10}
2025-07-26 21:11:33 modelling.py [INFO] Model training completed.
2025-07-26 21:11:34 modelling.py [INFO] Model RandomForestClassifier(max_depth=10, random_state=42) evaluated. Accuracy: 0.9605.
2025-07-26 21:12:31 modelling.py [INFO] Cross-validation accuracy: 0.9488
2025-07-26 21:12:51 modelling.py [INFO] Loaded .env file from: True
2025-07-26 21:12:52 httpx [INFO] HTTP Request: GET https://dagshub.com/api/v1/user "HTTP/1.1 200 OK"
2025-07-26 21:12:52 dagshub [INFO] Accessing as Rafaellsimarmata
2025-07-26 21:12:54 httpx [INFO] HTTP Request: GET https://dagshub.com/api/v1/repos/Rafaellsimarmata/workflow-CI-Rafael-Simarmata "HTTP/1.1 200 OK"
2025-07-26 21:12:55 httpx [INFO] HTTP Request: GET https://dagshub.com/api/v1/user "HTTP/1.1 200 OK"
2025-07-26 21:12:55 dagshub [INFO] Initialized MLflow to track repo "Rafaellsimarmata/workflow-CI-Rafael-Simarmata"
2025-07-26 21:12:55 dagshub [INFO] Repository Rafaellsimarmata/workflow-CI-Rafael-Simarmata initialized!
2025-07-26 21:12:55 modelling.py [INFO] Setting tracking URI to: http://localhost:5000
2025-07-26 21:12:55 modelling.py [INFO] MLflow setup completed
2025-07-26 21:12:55 modelling.py [INFO] Loading data from: fraud_detection_processed.csv
2025-07-26 21:12:55 modelling.py [INFO] Data loaded and split. Train: (1212, 9), Test: (304, 9)
2025-07-26 21:12:57 modelling.py [INFO] Model training started: rf. Parameters: {'n_estimators': 100, 'max_depth': 10}
2025-07-26 21:13:15 modelling.py [INFO] Model training completed.
2025-07-26 21:13:15 modelling.py [INFO] Model RandomForestClassifier(max_depth=10, random_state=42) evaluated. Accuracy: 0.9605.
2025-07-26 21:14:14 modelling.py [INFO] Cross-validation accuracy: 0.9488
2025-07-26 21:14:14 modelling.py [INFO] Metrics logged to MLflow.
2025-07-26 21:14:15 modelling.py [INFO] Confusion matrix logged as CSV and PNG to MLflow.
2025-07-26 21:14:16 modelling.py [INFO] Feature importance logged to MLflow.
2025-07-26 21:14:16 modelling.py [INFO] Metrics saved and logged to MLflow.
2025-07-26 21:14:24 modelling.py [INFO] Model artifact saved and logged to MLflow.
2025-07-26 21:14:24 modelling.py [INFO] Model rf trained and logged successfully.
2025-07-26 21:14:24 modelling.py [INFO] Run ID: 94ad9334a2d6424da66a266ee63b5032
2025-07-26 21:14:24 modelling.py [INFO] Accuracy: 0.9605
2025-07-26 21:14:24 modelling.py [INFO] Cross-validation accuracy: 0.9488
2025-07-26 21:14:24 modelling.py [INFO] Run ID saved to file.
2025-07-26 21:14:56 modelling.py [INFO] Loaded .env file from: True
2025-07-26 21:14:59 httpx [INFO] HTTP Request: GET https://dagshub.com/api/v1/user "HTTP/1.1 200 OK"
2025-07-26 21:14:59 dagshub [INFO] Accessing as Rafaellsimarmata
2025-07-26 21:15:06 httpx [INFO] HTTP Request: GET https://dagshub.com/api/v1/repos/Rafaellsimarmata/workflow-CI-Rafael-Simarmata "HTTP/1.1 200 OK"
2025-07-26 21:15:08 httpx [INFO] HTTP Request: GET https://dagshub.com/api/v1/user "HTTP/1.1 200 OK"
2025-07-26 21:15:08 dagshub [INFO] Initialized MLflow to track repo "Rafaellsimarmata/workflow-CI-Rafael-Simarmata"
2025-07-26 21:15:08 dagshub [INFO] Repository Rafaellsimarmata/workflow-CI-Rafael-Simarmata initialized!
2025-07-26 21:15:08 modelling.py [INFO] Setting tracking URI to: http://localhost:5000
2025-07-26 21:15:08 modelling.py [INFO] MLflow setup completed
2025-07-26 21:15:08 modelling.py [INFO] Loading data from: fraud_detection_processed.csv
2025-07-26 21:15:08 modelling.py [INFO] Data loaded and split. Train: (1212, 9), Test: (304, 9)
2025-07-26 21:15:11 modelling.py [INFO] Model training started: rf. Parameters: {'n_estimators': 100, 'max_depth': 10}
2025-07-26 21:15:28 modelling.py [INFO] Model training completed.
2025-07-26 21:15:29 modelling.py [INFO] Model RandomForestClassifier(max_depth=10, random_state=42) evaluated. Accuracy: 0.9605.
2025-07-26 21:16:25 modelling.py [INFO] Cross-validation accuracy: 0.9488
2025-07-26 21:16:25 modelling.py [INFO] Metrics logged to MLflow.
2025-07-26 21:16:26 modelling.py [INFO] Confusion matrix logged as CSV and PNG to MLflow.
2025-07-26 21:16:26 modelling.py [INFO] Feature importance logged to MLflow.
2025-07-26 21:16:26 modelling.py [INFO] Metrics saved and logged to MLflow.
2025-07-26 21:16:35 modelling.py [INFO] Model artifact saved and logged to MLflow.
2025-07-26 21:16:36 modelling.py [INFO] Model rf trained and logged successfully.
2025-07-26 21:16:36 modelling.py [INFO] Run ID: 50797d1a952f4bffada03b69cd709c52
2025-07-26 21:16:36 modelling.py [INFO] Accuracy: 0.9605
2025-07-26 21:16:36 modelling.py [INFO] Cross-validation accuracy: 0.9488
2025-07-26 21:16:36 modelling.py [INFO] Run ID saved to file.
2025-07-26 21:19:12 modelling.py [INFO] Loaded .env file from: True
2025-07-26 21:19:13 httpx [INFO] HTTP Request: GET https://dagshub.com/api/v1/repos/Rafaellsimarmata/workflow-CI-Rafael-Simarmata "HTTP/1.1 200 OK"
2025-07-26 21:19:13 dagshub [INFO] Initialized MLflow to track repo "Rafaellsimarmata/workflow-CI-Rafael-Simarmata"
2025-07-26 21:19:13 dagshub [INFO] Repository Rafaellsimarmata/workflow-CI-Rafael-Simarmata initialized!
2025-07-26 21:19:13 modelling.py [INFO] Setting tracking URI to: https://dagshub.com/Rafaellsimarmata/workflow-CI-Rafael-Simarmata.mlflow
2025-07-26 21:19:13 modelling.py [INFO] MLflow setup completed
2025-07-26 21:19:13 modelling.py [INFO] Loading data from: fraud_detection_processed.csv
2025-07-26 21:19:13 modelling.py [INFO] Data loaded and split. Train: (1212, 9), Test: (304, 9)
2025-07-26 21:23:23 modelling.py [ERROR] An error occurred when training model: API request to https://dagshub.com/Rafaellsimarmata/workflow-CI-Rafael-Simarmata.mlflow/api/2.0/mlflow/runs/get failed with exception HTTPSConnectionPool(host='dagshub.com', port=443): Max retries exceeded with url: /Rafaellsimarmata/workflow-CI-Rafael-Simarmata.mlflow/api/2.0/mlflow/runs/get?run_uuid=e90d48a2fd624513bc09b522627bd4af&run_id=e90d48a2fd624513bc09b522627bd4af (Caused by ResponseError('too many 500 error responses'))
urllib3.exceptions.ResponseError: too many 500 error responses

The above exception was the direct cause of the following exception:

Traceback (most recent call last):
  File "C:\Users\ACER\Documents\USU\Semester6\DBS_Journey\membangun_model_msml\.venv\Lib\site-packages\requests\adapters.py", line 667, in send
    resp = conn.urlopen(
        method=request.method,
    ...<9 lines>...
        chunked=chunked,
    )
  File "C:\Users\ACER\Documents\USU\Semester6\DBS_Journey\membangun_model_msml\.venv\Lib\site-packages\urllib3\connectionpool.py", line 942, in urlopen
    return self.urlopen(
           ~~~~~~~~~~~~^
        method,
        ^^^^^^^
    ...<13 lines>...
        **response_kw,
        ^^^^^^^^^^^^^^
    )
    ^
  File "C:\Users\ACER\Documents\USU\Semester6\DBS_Journey\membangun_model_msml\.venv\Lib\site-packages\urllib3\connectionpool.py", line 942, in urlopen
    return self.urlopen(
           ~~~~~~~~~~~~^
        method,
        ^^^^^^^
    ...<13 lines>...
        **response_kw,
        ^^^^^^^^^^^^^^
    )
    ^
  File "C:\Users\ACER\Documents\USU\Semester6\DBS_Journey\membangun_model_msml\.venv\Lib\site-packages\urllib3\connectionpool.py", line 942, in urlopen
    return self.urlopen(
           ~~~~~~~~~~~~^
        method,
        ^^^^^^^
    ...<13 lines>...
        **response_kw,
        ^^^^^^^^^^^^^^
    )
    ^
  [Previous line repeated 4 more times]
  File "C:\Users\ACER\Documents\USU\Semester6\DBS_Journey\membangun_model_msml\.venv\Lib\site-packages\urllib3\connectionpool.py", line 932, in urlopen
    retries = retries.increment(method, url, response=response, _pool=self)
  File "C:\Users\ACER\Documents\USU\Semester6\DBS_Journey\membangun_model_msml\.venv\Lib\site-packages\urllib3\util\retry.py", line 519, in increment
    raise MaxRetryError(_pool, url, reason) from reason  # type: ignore[arg-type]
    ^^^^^^^^^^^^^^^^^^^^^^^^^^^^^^^^^^^^^^^^^^^^^^^^^^^
urllib3.exceptions.MaxRetryError: HTTPSConnectionPool(host='dagshub.com', port=443): Max retries exceeded with url: /Rafaellsimarmata/workflow-CI-Rafael-Simarmata.mlflow/api/2.0/mlflow/runs/get?run_uuid=e90d48a2fd624513bc09b522627bd4af&run_id=e90d48a2fd624513bc09b522627bd4af (Caused by ResponseError('too many 500 error responses'))

During handling of the above exception, another exception occurred:

Traceback (most recent call last):
  File "C:\Users\ACER\Documents\USU\Semester6\DBS_Journey\membangun_model_msml\.venv\Lib\site-packages\mlflow\utils\rest_utils.py", line 184, in http_request
    return _get_http_response_with_retries(
        method,
    ...<10 lines>...
        **kwargs,
    )
  File "C:\Users\ACER\Documents\USU\Semester6\DBS_Journey\membangun_model_msml\.venv\Lib\site-packages\mlflow\utils\request_utils.py", line 237, in _get_http_response_with_retries
    return session.request(method, url, allow_redirects=allow_redirects, **kwargs)
           ~~~~~~~~~~~~~~~^^^^^^^^^^^^^^^^^^^^^^^^^^^^^^^^^^^^^^^^^^^^^^^^^^^^^^^^
  File "C:\Users\ACER\Documents\USU\Semester6\DBS_Journey\membangun_model_msml\.venv\Lib\site-packages\requests\sessions.py", line 589, in request
    resp = self.send(prep, **send_kwargs)
  File "C:\Users\ACER\Documents\USU\Semester6\DBS_Journey\membangun_model_msml\.venv\Lib\site-packages\requests\sessions.py", line 703, in send
    r = adapter.send(request, **kwargs)
  File "C:\Users\ACER\Documents\USU\Semester6\DBS_Journey\membangun_model_msml\.venv\Lib\site-packages\requests\adapters.py", line 691, in send
    raise RetryError(e, request=request)
requests.exceptions.RetryError: HTTPSConnectionPool(host='dagshub.com', port=443): Max retries exceeded with url: /Rafaellsimarmata/workflow-CI-Rafael-Simarmata.mlflow/api/2.0/mlflow/runs/get?run_uuid=e90d48a2fd624513bc09b522627bd4af&run_id=e90d48a2fd624513bc09b522627bd4af (Caused by ResponseError('too many 500 error responses'))

During handling of the above exception, another exception occurred:

Traceback (most recent call last):
  File "C:\Users\ACER\Documents\USU\Semester6\DBS_Journey\membangun_model_msml\MLProject\modelling.py", line 240, in main
    run_id, metrics, cv_accuracy = model_train(
                                   ~~~~~~~~~~~^
        X_train, X_test, y_train, y_test, model_name, params
        ^^^^^^^^^^^^^^^^^^^^^^^^^^^^^^^^^^^^^^^^^^^^^^^^^^^^
    )
    ^
  File "C:\Users\ACER\Documents\USU\Semester6\DBS_Journey\membangun_model_msml\MLProject\modelling.py", line 109, in model_train
    with mlflow.start_run(run_name=f'{model_name}_run_ci') as run:
         ~~~~~~~~~~~~~~~~^^^^^^^^^^^^^^^^^^^^^^^^^^^^^^^^^
  File "C:\Users\ACER\Documents\USU\Semester6\DBS_Journey\membangun_model_msml\.venv\Lib\site-packages\mlflow\tracking\fluent.py", line 368, in start_run
    active_run_obj = client.get_run(existing_run_id)
  File "C:\Users\ACER\Documents\USU\Semester6\DBS_Journey\membangun_model_msml\.venv\Lib\site-packages\mlflow\tracking\client.py", line 251, in get_run
    return self._tracking_client.get_run(run_id)
           ~~~~~~~~~~~~~~~~~~~~~~~~~~~~~^^^^^^^^
  File "C:\Users\ACER\Documents\USU\Semester6\DBS_Journey\membangun_model_msml\.venv\Lib\site-packages\mlflow\tracking\_tracking_service\client.py", line 108, in get_run
    return self.store.get_run(run_id)
           ~~~~~~~~~~~~~~~~~~^^^^^^^^
  File "C:\Users\ACER\Documents\USU\Semester6\DBS_Journey\membangun_model_msml\.venv\Lib\site-packages\mlflow\store\tracking\rest_store.py", line 177, in get_run
    response_proto = self._call_endpoint(GetRun, req_body)
  File "C:\Users\ACER\Documents\USU\Semester6\DBS_Journey\membangun_model_msml\.venv\Lib\site-packages\mlflow\store\tracking\rest_store.py", line 90, in _call_endpoint
    return call_endpoint(self.get_host_creds(), endpoint, method, json_body, response_proto)
  File "C:\Users\ACER\Documents\USU\Semester6\DBS_Journey\membangun_model_msml\.venv\Lib\site-packages\mlflow\utils\rest_utils.py", line 397, in call_endpoint
    response = http_request(**call_kwargs)
  File "C:\Users\ACER\Documents\USU\Semester6\DBS_Journey\membangun_model_msml\.venv\Lib\site-packages\mlflow\utils\rest_utils.py", line 207, in http_request
    raise MlflowException(f"API request to {url} failed with exception {e}")
mlflow.exceptions.MlflowException: API request to https://dagshub.com/Rafaellsimarmata/workflow-CI-Rafael-Simarmata.mlflow/api/2.0/mlflow/runs/get failed with exception HTTPSConnectionPool(host='dagshub.com', port=443): Max retries exceeded with url: /Rafaellsimarmata/workflow-CI-Rafael-Simarmata.mlflow/api/2.0/mlflow/runs/get?run_uuid=e90d48a2fd624513bc09b522627bd4af&run_id=e90d48a2fd624513bc09b522627bd4af (Caused by ResponseError('too many 500 error responses'))
2025-07-26 21:30:01 modelling.py [INFO] Loaded .env file from: True
2025-07-26 21:30:35 modelling.py [INFO] Loaded .env file from: True
2025-07-26 21:30:35 modelling.py [INFO] Setting tracking URI to: http://localhost:5000
2025-07-26 21:30:35 modelling.py [INFO] MLflow setup completed
2025-07-26 21:30:35 modelling.py [INFO] Loading data from: fraud_detection_processed.csv
2025-07-26 21:30:35 modelling.py [INFO] Data loaded and split. Train: (1212, 9), Test: (304, 9)
2025-07-26 21:38:28 modelling.py [INFO] Loaded .env file from: True
2025-07-26 21:38:28 modelling.py [INFO] Setting tracking URI to: http://localhost:5000
2025-07-26 21:38:28 modelling.py [INFO] MLflow setup completed
2025-07-26 21:38:28 modelling.py [INFO] Loading data from: fraud_detection_processed.csv
2025-07-26 21:38:28 modelling.py [INFO] Data loaded and split. Train: (1212, 9), Test: (304, 9)
